<?xml version="1.0" encoding="UTF-8" standalone="yes"?>
<robot xmlns:ns2="http://www.ros.org" name="eve_r3_head">
    <joint name="j_neck_y" type="revolute">
        <origin xyz="0.00646 0.00085 0.67201" rpy="0.0 0.0 0.0"/>
        <parent link="pelvis"/>
        <child link="head"/>
        <axis xyz="0.0 1.0 0.0"/>
        <limit lower="-0.0872664626" upper="0.698132" effort="-1.0" velocity="-1.0"/>
    </joint>
    <link name="head">
        <inertial>
            <origin xyz="0.02485953 -0.00373226 0.11157957" rpy="0.0 0.0 0.0"/>
            <mass value="1.84975554"/>
            <inertia ixx="0.01343625" ixy="-1.5664E-4" ixz="-0.00146014" iyy="0.01517256" iyz="1.7375E-4" izz="0.00763704"/>
        </inertial>
        <visual>
            <origin xyz="0.0 0.0 0.0" rpy="1.5707963 0.0 1.5707963"/>
            <geometry>
                <mesh filename="package://eve_r3_description/meshes/head.obj" scale="1 1 1"/>
            </geometry>
        </visual>
    </link>
    
    <gazebo reference="head">

        <sensor type="depth" name="kinect_azure">

          <!-- Set always_on only sensor, not on plugin -->
          <always_on>0</always_on>

          <!-- Set update_rate only sensor, not on plugin -->
          <update_rate>25</update_rate>
          <pose frame="">0.116669 0 0.17015 0 0.174533 0</pose>

          <camera name="camera_name">
            <image>
                <width>2048</width>
                <height>1536</height>
                <format>R8G8B8</format>
            </image>
            <horizontal_fov>1.5708</horizontal_fov>
            <clip>
                <near>0.2</near>
                <far>100</far>
            </clip>
          </camera>

          <plugin name="camera_plugin" filename="libgazebo_ros_camera.so">

             <frame_name>kinect_azure_camera_name</frame_name>
             <hack_baseline>0.07</hack_baseline>
             <min_depth>0.24</min_depth>
             <max_depth>2.88</max_depth>
          </plugin>
        </sensor>
    </gazebo>

    
    
</robot>
