<?xml version="1.0" encoding="UTF-8" standalone="yes"?>
<robot xmlns:ns2="http://www.ros.org" name="eve_r3_left_arm">
    <joint name="j_l_shoulder_y" type="revolute">
        <origin xyz="0.010525 0.207221 0.545525" rpy="0.253261563 0.0 -0.261799"/>
        <parent link="l_shoulder"/>
        <child link="l_scapula"/>
        <axis xyz="0.0 1.0 0.0"/>
        <limit lower="-2.4240878" upper="0.981049573" effort="-1.0" velocity="-1.0"/>
    </joint>
    <link name="l_scapula">
        <inertial>
            <origin xyz="5.1063E-4 -0.06534731 0.02796782" rpy="0.0 0.0 0.0"/>
            <mass value="3.00902868"/>
            <inertia ixx="0.01028211" ixy="-4.893E-5" ixz="-7.063E-5" iyy="0.01156515" iyz="-0.00119105" izz="0.01333081"/>
        </inertial>
        <visual>
            <origin xyz="0.0 0.0 0.0" rpy="1.5707963 0.0 3.14159"/>
            <geometry>
                <mesh filename="package://eve_r3_description/meshes/scapula.obj" scale="1 1 1"/>
            </geometry>
        </visual>
    </link>
    <joint name="j_l_shoulder_x" type="revolute">
        <origin xyz="0.0 0.0 0.0" rpy="-0.253261563 0.0 0.0"/>
        <parent link="l_scapula"/>
        <child link="l_shoulder"/>
        <axis xyz="1.0 0.0 0.0"/>
        <limit lower="-0.0872665" upper="2.0943951" effort="-1.0" velocity="-1.0"/>
    </joint>
    <link name="l_shoulder">
        <inertial>
            <origin xyz="-1.673E-5 1.9377E-4 -0.01871047" rpy="0.0 0.0 0.0"/>
            <mass value="0.62091759"/>
            <inertia ixx="9.7077E-4" ixy="3.76E-6" ixz="-1.39E-6" iyy="0.00133514" iyz="5.96E-6" izz="7.8248E-4"/>
        </inertial>
        <visual>
            <origin xyz="0.0 0.0 0.0" rpy="3.14159 0.0 0.0"/>
            <geometry>
                <mesh filename="package://eve_r3_description/meshes/shoulder.obj" scale="1 1 1"/>
            </geometry>
        </visual>
    </link>
    <joint name="j_l_shoulder_z" type="revolute">
        <origin xyz="0.0 0.0 0.0" rpy="0.0 0.0 0.261799"/>
        <parent link="l_shoulder"/>
        <child link="l_upper_arm"/>
        <axis xyz="0.0 0.0 1.0"/>
        <limit lower="-1.4660761" upper="0.5410525" effort="-1.0" velocity="-1.0"/>
    </joint>
    <link name="l_upper_arm">
        <inertial>
            <origin xyz="-0.00698778 1.1145E-4 -0.11499125" rpy="0.0 0.0 0.0"/>
            <mass value="3.32260186"/>
            <inertia ixx="0.01596325" ixy="8.08E-6" ixz="-5.5061E-4" iyy="0.01552407" iyz="4.445E-5" izz="0.00620843"/>
        </inertial>
        <visual>
            <origin xyz="0.0 0.0 0.0" rpy="1.5707963 0.0 3.14159"/>
            <geometry>
                <mesh filename="package://eve_r3_description/meshes/upper_arm.obj" scale="1 1 1"/>
            </geometry>
        </visual>
    </link>
    <joint name="j_l_elbow_y" type="revolute">
        <origin xyz="0.0 0.0 -0.313989" rpy="0.0 0.0 0.0"/>
        <parent link="l_upper_arm"/>
        <child link="l_elbow"/>
        <axis xyz="0.0 1.0 0.0"/>
        <limit lower="-2.18166" upper="0.0" effort="-1.0" velocity="-1.0"/>
    </joint>
    <link name="l_elbow">
        <inertial>
            <origin xyz="6.509E-5 2.07E-6 -0.00890634" rpy="0.0 0.0 0.0"/>
            <mass value="0.46228452"/>
            <inertia ixx="8.234E-4" ixy="-1.0E-8" ixz="1.04E-6" iyy="3.6507E-4" iyz="-3.0E-8" izz="6.1458E-4"/>
        </inertial>
        <visual>
            <origin xyz="0.0 0.0 0.0" rpy="0.0 3.14159 1.5707963"/>
            <geometry>
                <mesh filename="package://eve_r3_description/meshes/elbow.obj" scale="1 1 1"/>
            </geometry>
        </visual>
    </link>
    <joint name="j_l_elbow_z" type="revolute">
        <origin xyz="0.0 0.0 0.0" rpy="0.0 0.0 0.0"/>
        <parent link="l_elbow"/>
        <child link="l_lower_arm"/>
        <axis xyz="0.0 0.0 1.0"/>
        <limit lower="-1.5708" upper="0.7854" effort="-1.0" velocity="-1.0"/>
    </joint>
    <link name="l_lower_arm">
        <inertial>
            <origin xyz="5.231E-5 -6.031E-5 -0.14272377" rpy="0.0 0.0 0.0"/>
            <mass value="1.72646966"/>
            <inertia ixx="0.00752577" ixy="3.09E-6" ixz="-3.88E-6" iyy="0.0078581" iyz="-4.25E-6" izz="0.00189705"/>
        </inertial>
        <visual>
            <origin xyz="0.0 0.0 -0.29285" rpy="0.0 3.14159 0.0"/>
            <geometry>
                <mesh filename="package://eve_r3_description/meshes/forearm.obj" scale="1 1 1"/>
            </geometry>
        </visual>
    </link>
    <joint name="j_l_wrist_y" type="revolute">
        <origin xyz="0.0 0.0 -0.29285" rpy="0.0 0.0 0.0"/>
        <parent link="l_lower_arm"/>
        <child link="l_wrist"/>
        <axis xyz="0.0 1.0 0.0"/>
        <limit lower="-0.785398" upper="0.785398" effort="-1.0" velocity="-1.0"/>
    </joint>
    <link name="l_wrist">
        <inertial>
            <origin xyz="-1.859E-4 -5.5E-5 -0.001294" rpy="0.0 0.0 0.0"/>
            <mass value="0.3582051"/>
            <inertia ixx="2.896E-4" ixy="2.1E-6" ixz="1.1E-6" iyy="2.335E-4" iyz="3.0E-7" izz="3.221E-4"/>
        </inertial>
        <visual>
            <origin xyz="0.0 0.0 0.0" rpy="0.0 0.0 1.5708"/>
            <geometry>
                <mesh filename="package://eve_r3_description/meshes/wrist.obj" scale="1 1 1"/>
            </geometry>
        </visual>
    </link>
    <joint name="j_l_wrist_x" type="revolute">
        <origin xyz="0.0 0.0 0.0" rpy="0.0 0.0 0.0"/>
        <parent link="l_wrist"/>
        <child link="l_palm"/>
        <axis xyz="1.0 0.0 0.0"/>
        <limit lower="-1.5708" upper="0.523599" effort="-1.0" velocity="-1.0"/>
    </joint>
    <link name="l_palm">
        <inertial>
            <origin xyz="-0.0038054 0.002091 -0.03373019" rpy="0.0 0.0 0.0"/>
            <mass value="0.22529206"/>
            <inertia ixx="2.4167E-4" ixy="-5.6E-7" ixz="3.083E-5" iyy="4.0895E-4" iyz="-3.58E-6" izz="2.7633E-4"/>
        </inertial>
        <visual>
            <origin xyz="0.0 0.0 0.0" rpy="-1.5707963 0.0 3.14159"/>
            <geometry>
                <mesh filename="package://eve_r3_description/meshes/palm.obj" scale="1 1 1"/>
            </geometry>
        </visual>
    </link>
</robot>
