<?xml version="1.0" encoding="UTF-8" standalone="yes"?>
<robot xmlns:ns2="http://www.ros.org" name="eve_r3_head">
    <joint name="j_neck_y" type="revolute">
        <origin xyz="-0.004458 0.0 0.680766" rpy="0.0 0.0 0.0"/>
        <parent link="Root_1"/>
        <child link="head"/>
        <axis xyz="0.0 1.0 0.0"/>
        <limit lower="-0.0872664626" upper="0.698132" effort="-1.0" velocity="-1.0"/>
    </joint>
    <link name="head">
        <inertial>
            <origin xyz="0.02785419 -0.00406286 0.10870548" rpy="0.0 0.0 0.0"/>
            <mass value="1.45569784"/>
            <inertia ixx="0.00946644" ixy="-1.8919E-4" ixz="-0.00165312" iyy="0.01133976" iyz="1.2182E-4" izz="0.00442166"/>
        </inertial>
        <visual>
            <origin xyz="0.0 0.0 0.0" rpy="1.5707963 0.0 1.5707963"/>
            <geometry>
                <mesh filename="package://eve_r3_description/meshes/head.obj" scale="1 1 1"/>
            </geometry>
        </visual>
    </link>
    <link name="Root_1">
        <inertial>
            <origin xyz="0.0 0.0 0.0" rpy="0.0 0.0 0.0"/>
            <mass value="0.0"/>
            <inertia ixx="0.0" ixy="-0.0" ixz="-0.0" iyy="0.0" iyz="-0.0" izz="0.0"/>
        </inertial>
        <visual>
            <origin xyz="0.0 0.0 0.0" rpy="0.0 0.0 0.0"/>
            <geometry>
                <mesh filename="package://" scale="1 1 1"/>
            </geometry>
        </visual>
    </link>
    <gazebo reference="head">
        <sensor name="realsense" type="camera">
            <camera>
                <image>
                    <width>640</width>
                    <height>480</height>
                    <format>R8G8B8</format>
	        </image>
                <horizontal_fov>1.487021</horizontal_fov>
                <clip>
                    <near>0.2</near>
                    <far>10</far>
	        </clip>
	      </camera>
            <update_rate>6</update_rate>
            <pose frame="">0.116669 0 0.17015 0 0.174533 0</pose>
	    </sensor>
    </gazebo>
</robot>
