<?xml version="1.0" encoding="UTF-8" standalone="yes"?>
<robot xmlns:ns2="http://www.ros.org" name="eve_r3_right_arm" xmlns:xi="http://www.w3.org/2003/XInclude">
    <joint name="j_r_shoulder_y" type="revolute">
        <origin xyz="0.010525 -0.207221 0.545525" rpy="-0.253261563 0.0 0.261799"/>
        <parent link="pelvis"/>
        <child link="r_scapula"/>
        <axis xyz="0.0 1.0 0.0"/>
        <limit lower="-2.4240878" upper="0.981049573" effort="-1.0" velocity="-1.0"/>
    </joint>
    <link name="r_scapula">
        <inertial>
            <origin xyz="6.1099E-4 0.06306661 0.03032448" rpy="0.0 0.0 0.0"/>
            <mass value="2.75566786"/>
            <inertia ixx="0.00936557" ixy="2.264E-5" ixz="-7.112E-5" iyy="0.01079015" iyz="8.423E-4" izz="0.01267759"/>
        </inertial>
        <visual>
            <origin xyz="0.0 0.0 0.0" rpy="1.5707963 0.0 0.0"/>
            <geometry>
                <mesh filename="package://eve_r3_description/meshes/scapula.obj" scale="1 1 1"/>
            </geometry>
        </visual>
    </link>
    <joint name="j_r_shoulder_x" type="revolute">
        <origin xyz="0.0 0.0 0.0" rpy="0.253261563 0.0 0.0"/>
        <parent link="r_scapula"/>
        <child link="r_shoulder"/>
        <axis xyz="1.0 0.0 0.0"/>
        <limit lower="-2.0943951" upper="0.0872665" effort="-1.0" velocity="-1.0"/>
    </joint>
    <link name="r_shoulder">
        <inertial>
            <origin xyz="0.0 -7.0614E-4 -0.01975465" rpy="0.0 0.0 0.0"/>
            <mass value="0.70264272"/>
            <inertia ixx="0.00115475" ixy="-3.2E-7" ixz="-1.4E-7" iyy="0.00143713" iyz="2.63E-6" izz="9.4633E-4"/>
        </inertial>
        <visual>
            <origin xyz="0.0 0.0 0.0" rpy="3.14159 0 0"/>
            <geometry>
                <mesh filename="package://eve_r3_description/meshes/shoulder.obj" scale="1 1 1"/>
            </geometry>
        </visual>
    </link>
    <joint name="j_r_shoulder_z" type="revolute">
        <origin xyz="0.0 0.0 0.0" rpy="0.0 0.0 -0.261799"/>
        <parent link="r_shoulder"/>
        <child link="r_upper_arm"/>
        <axis xyz="0.0 0.0 1.0"/>
        <limit lower="-0.5410525" upper="1.4660761" effort="-1.0" velocity="-1.0"/>
    </joint>
    <link name="r_upper_arm">
        <inertial>
            <origin xyz="-0.0062579 3.507E-5 -0.17187666" rpy="0.0 0.0 0.0"/>
            <mass value="2.92531724"/>
            <inertia ixx="0.01341653" ixy="-6.4E-7" ixz="-2.9063E-4" iyy="0.01287847" iyz="-3.08E-6" izz="0.00487381"/>
        </inertial>
        <visual>
            <origin xyz="0.0 0.0 0.0" rpy="1.5707963 0.0 3.14159"/>
            <geometry>
                <mesh filename="package://eve_r3_description/meshes/upper_arm.obj" scale="1 1 1"/>
            </geometry>
        </visual>
    </link>
    <joint name="j_r_elbow_y" type="revolute">
        <origin xyz="0.0 0.0 -0.313989" rpy="0.0 0.0 0.0"/>
        <parent link="r_upper_arm"/>
        <child link="r_elbow"/>
        <axis xyz="0.0 1 0.0"/>
        <limit lower="-2.18166" upper="0.0" effort="-1.0" velocity="-1.0"/>
    </joint>
    <link name="r_elbow">
        <inertial>
            <origin xyz="5.494E-5 0.0 -0.00888504" rpy="0.0 0.0 0.0"/>
            <mass value="0.46261553"/>
            <inertia ixx="8.227E-4" ixy="-0.0" ixz="9.6E-7" iyy="3.6441E-4" iyz="-0.0" izz="6.1472E-4"/>
        </inertial>
        <visual>
            <origin xyz="0.0 0.0 0.0" rpy="0.0 3.14159 1.5707963"/>
            <geometry>
                <mesh filename="package://eve_r3_description/meshes/elbow.obj" scale="1 1 1"/>
            </geometry>
        </visual>
    </link>
    <joint name="j_r_elbow_z" type="revolute">
        <origin xyz="0.0 0.0 0.0" rpy="0.0 0.0 0.0"/>
        <parent link="r_elbow"/>
        <child link="r_lower_arm"/>
        <axis xyz="0.0 0.0 1"/>
        <limit lower="-0.7854" upper="1.5708" effort="-1.0" velocity="-1.0"/>
    </joint>
    <link name="r_lower_arm">
        <inertial>
            <origin xyz="-4.326E-5 3.091E-5 -0.13751046" rpy="0.0 0.0 0.0"/>
            <mass value="1.63933464"/>
            <inertia ixx="0.00678741" ixy="1.11E-6" ixz="-1.253E-5" iyy="0.00706746" iyz="1.485E-5" izz="0.00183806"/>
        </inertial>
        <visual>
            <origin xyz="0.0 0.0 -0.292850" rpy="0.0 3.14159 0.0"/>
            <geometry>
                <mesh filename="package://eve_r3_description/meshes/forearm.obj" scale="1 1 1"/>
            </geometry>
        </visual>
    </link>
    <joint name="j_r_wrist_y" type="revolute">
        <origin xyz="0.0 0.0 -0.292850" rpy="0.0 0.0 0.0"/>
        <parent link="r_lower_arm"/>
        <child link="r_wrist"/>
        <axis xyz="0.0 1 0.0"/>
        <limit lower="-0.785398" upper="0.785398" effort="-1.0" velocity="-1.0"/>
    </joint>
    <link name="r_wrist">
        <inertial>
            <origin xyz="0.00240142 7.9666E-4 -0.00125392" rpy="0.0 0.0 0.0"/>
            <mass value="0.30363399"/>
            <inertia ixx="1.8188E-4" ixy="2.27E-6" ixz="-2.16E-6" iyy="1.6139E-4" iyz="-9.5E-7" izz="2.7335E-4"/>
        </inertial>
        <visual>
            <origin xyz="0.0 0.0 0.0" rpy="0.0 0.0 1.5708"/>
            <geometry>
                <mesh filename="package://eve_r3_description/meshes/wrist.obj" scale="1 1 1"/>
            </geometry>
        </visual>
    </link>
    <joint name="j_r_wrist_x" type="revolute">
        <origin xyz="0.0 0.0 0.0" rpy="0.0 0.0 0.0"/>
        <parent link="r_wrist"/>
        <child link="r_palm"/>
        <axis xyz="1 0.0 0.0"/>
        <limit lower="-0.523599" upper="1.5708" effort="-1.0" velocity="-1.0"/>
    </joint>
    <link name="r_palm">
        <inertial>
            <origin xyz="0.00618476 -0.00346679 -0.01888817" rpy="0.0 0.0 0.0"/>
            <mass value="0.1486378"/>
            <inertia ixx="1.177E-4" ixy="-2.72E-6" ixz="-1.656E-5" iyy="2.8407E-4" iyz="-5.49E-6" izz="2.1805E-4"/>
        </inertial>
        <visual>
            <origin xyz="0.0 0.0 0.0" rpy="-1.5707963 0.0 0.0"/>
            <geometry>
                <mesh filename="package://eve_r3_description/meshes/palm.obj" scale="1 1 1"/>
            </geometry>
        </visual>
    </link>
    
    
   <xi:include href="qbhand.right.in.urdf" xpointer="xpointer(//robot/*)"/>
    
</robot>
