<?xml version="1.0" encoding="UTF-8" standalone="yes"?>
<robot xmlns:ns2="http://www.ros.org" name="eve_r3_right_arm">
    <joint name="j_r_shoulder_y" type="revolute">
        <origin xyz="0.010525 -0.207221 0.545525" rpy="-0.253261563 0.0 0.261799"/>
        <parent link="r_shoulder"/>
        <child link="r_scapula"/>
        <axis xyz="0.0 1.0 0.0"/>
        <limit lower="-2.4240878" upper="0.981049573" effort="-1.0" velocity="-1.0"/>
    </joint>
    <link name="r_scapula">
        <inertial>
            <origin xyz="3.7947E-4 0.06518341 0.02816495" rpy="0.0 0.0 0.0"/>
            <mass value="3.00220101"/>
            <inertia ixx="0.01020711" ixy="2.03E-6" ixz="-3.444E-5" iyy="0.01151732" iyz="0.00114803" izz="0.01329451"/>
        </inertial>
        <visual>
            <origin xyz="0.0 0.0 0.0" rpy="1.5707963 0.0 0.0"/>
            <geometry>
                <mesh filename="package://eve_r3_description/meshes/scapula.obj" scale="1 1 1"/>
            </geometry>
        </visual>
    </link>
    <joint name="j_r_shoulder_x" type="revolute">
        <origin xyz="0.0 0.0 0.0" rpy="0.253261563 0.0 0.0"/>
        <parent link="r_scapula"/>
        <child link="r_shoulder"/>
        <axis xyz="1.0 0.0 0.0"/>
        <limit lower="-2.0943951" upper="0.0872665" effort="-1.0" velocity="-1.0"/>
    </joint>
    <link name="r_shoulder">
        <inertial>
            <origin xyz="1.673E-5 -1.9377E-4 -0.01871047" rpy="0.0 0.0 0.0"/>
            <mass value="0.62091759"/>
            <inertia ixx="9.7077E-4" ixy="3.76E-6" ixz="1.39E-6" iyy="0.00133514" iyz="-5.96E-6" izz="7.8248E-4"/>
        </inertial>
        <visual>
            <origin xyz="0.0 0.0 0.0" rpy="3.14159 0.0 0.0"/>
            <geometry>
                <mesh filename="package://eve_r3_description/meshes/shoulder.obj" scale="1 1 1"/>
            </geometry>
        </visual>
    </link>
    <joint name="j_r_shoulder_z" type="revolute">
        <origin xyz="0.0 0.0 0.0" rpy="0.0 0.0 -0.261799"/>
        <parent link="r_shoulder"/>
        <child link="r_upper_arm"/>
        <axis xyz="0.0 0.0 1.0"/>
        <limit lower="-0.5410525" upper="1.4660761" effort="-1.0" velocity="-1.0"/>
    </joint>
    <link name="r_upper_arm">
        <inertial>
            <origin xyz="-0.00699737 1.3778E-4 -0.1740665" rpy="0.0 0.0 0.0"/>
            <mass value="3.32084455"/>
            <inertia ixx="0.01594152" ixy="8.55E-6" ixz="-5.4922E-4" iyy="0.01550579" iyz="3.617E-5" izz="0.00620232"/>
        </inertial>
        <visual>
            <origin xyz="0.0 0.0 0.0" rpy="1.5707963 0.0 3.14159"/>
            <geometry>
                <mesh filename="package://eve_r3_description/meshes/upper_arm.obj" scale="1 1 1"/>
            </geometry>
        </visual>
    </link>
    <joint name="j_r_elbow_y" type="revolute">
        <origin xyz="0.0 0.0 -0.313989" rpy="0.0 0.0 0.0"/>
        <parent link="r_upper_arm"/>
        <child link="r_elbow"/>
        <axis xyz="0.0 1.0 0.0"/>
        <limit lower="-2.18166" upper="0.0" effort="-1.0" velocity="-1.0"/>
    </joint>
    <link name="r_elbow">
        <inertial>
            <origin xyz="6.557E-5 1.91E-6 -0.00890628" rpy="0.0 0.0 0.0"/>
            <mass value="0.4622891"/>
            <inertia ixx="8.234E-4" ixy="-2.0E-8" ixz="1.04E-6" iyy="3.6507E-4" iyz="-3.0E-8" izz="6.1458E-4"/>
        </inertial>
        <visual>
            <origin xyz="0.0 0.0 0.0" rpy="0.0 3.14159 1.5707963"/>
            <geometry>
                <mesh filename="package://eve_r3_description/meshes/elbow.obj" scale="1 1 1"/>
            </geometry>
        </visual>
    </link>
    <joint name="j_r_elbow_z" type="revolute">
        <origin xyz="0.0 0.0 0.0" rpy="0.0 0.0 0.0"/>
        <parent link="r_elbow"/>
        <child link="r_lower_arm"/>
        <axis xyz="0.0 0.0 1.0"/>
        <limit lower="-0.7854" upper="1.5708" effort="-1.0" velocity="-1.0"/>
    </joint>
    <link name="r_lower_arm">
        <inertial>
            <origin xyz="4.924E-5 -7.579E-5 -0.14272507" rpy="0.0 0.0 0.0"/>
            <mass value="1.72645167"/>
            <inertia ixx="0.00752527" ixy="2.55E-6" ixz="-3.2E-6" iyy="0.00785805" iyz="-8.5E-7" izz="0.00189704"/>
        </inertial>
        <visual>
            <origin xyz="0.0 0.0 -0.29285" rpy="0.0 3.14159 0.0"/>
            <geometry>
                <mesh filename="package://eve_r3_description/meshes/forearm.obj" scale="1 1 1"/>
            </geometry>
        </visual>
    </link>
    <joint name="j_r_wrist_y" type="revolute">
        <origin xyz="0.0 0.0 -0.29285" rpy="0.0 0.0 0.0"/>
        <parent link="r_lower_arm"/>
        <child link="r_wrist"/>
        <axis xyz="0.0 1.0 0.0"/>
        <limit lower="-0.785398" upper="0.785398" effort="-1.0" velocity="-1.0"/>
    </joint>
    <link name="r_wrist">
        <inertial>
            <origin xyz="1.859E-4 5.5E-5 -0.001294" rpy="0.0 0.0 0.0"/>
            <mass value="0.3582051"/>
            <inertia ixx="2.896E-4" ixy="2.1E-6" ixz="-1.1E-6" iyy="2.335E-4" iyz="-3.0E-7" izz="3.221E-4"/>
        </inertial>
        <visual>
            <origin xyz="0.0 0.0 0.0" rpy="0.0 0.0 1.5708"/>
            <geometry>
                <mesh filename="package://eve_r3_description/meshes/wrist.obj" scale="1 1 1"/>
            </geometry>
        </visual>
    </link>
    <joint name="j_r_wrist_x" type="revolute">
        <origin xyz="0.0 0.0 0.0" rpy="0.0 0.0 0.0"/>
        <parent link="r_wrist"/>
        <child link="r_palm"/>
        <axis xyz="1.0 0.0 0.0"/>
        <limit lower="-0.523599" upper="1.5708" effort="-1.0" velocity="-1.0"/>
    </joint>
    <link name="r_palm">
        <inertial>
            <origin xyz="0.0038054 -0.002091 -0.03373019" rpy="0.0 0.0 0.0"/>
            <mass value="0.22529206"/>
            <inertia ixx="2.4167E-4" ixy="-5.6E-7" ixz="-3.083E-5" iyy="4.0895E-4" iyz="3.58E-6" izz="2.7633E-4"/>
        </inertial>
        <visual>
            <origin xyz="0.0 0.0 0.0" rpy="-1.5707963 0.0 0.0"/>
            <geometry>
                <mesh filename="package://eve_r3_description/meshes/palm.obj" scale="1 1 1"/>
            </geometry>
        </visual>
    </link>
</robot>
