<?xml version="1.0" encoding="utf-8"?>
<robot name="robotiq_hand-e">
  <material name="lhand_rep_BlackMetal">
    <color rgba="0.0634 0.0634 0.0634 1" />
  </material>
  <material name="lhand_rep_Chrome">
    <color rgba="0.5 0.5 0.5 1" />
  </material>
  <link name="lhand_base">
    <inertial>
      <origin rpy="0 0 0" xyz="0 0 0.050025" />
      <mass value="1" />
      <inertia ixx="0.0011831687297672" ixy="0" ixz="0" iyy="0.0011831687297672" iyz="0" izz="0.000698003452271223" />
    </inertial>
    <visual name="Housing">
      <geometry>
        <mesh filename="package://robotiq_hand-e/meshes/Housing.obj" scale="0.01 0.01 0.01" />
      </geometry>
      <material name="lhand_rep_BlackMetal" />
    </visual>
    <visual name="Bolts">
      <origin xyz="0 0 0.04595" />
      <geometry>
        <mesh filename="package://robotiq_hand-e/meshes/Bolts.obj" scale="0.01 0.01 0.01" />
      </geometry>
      <material name="lhand_rep_Chrome" />
    </visual>
    <collision name="Housing_Collision_1">
      <origin xyz="0 0 0.050025" />
      <geometry>
        <cylinder length="0.10005" radius="0.0375" />
      </geometry>
    </collision>
  </link>
  <joint name="lhand_base_fixed_joint" type="fixed">
    <origin rpy="3.14 0 0" xyz="0 0 -0.06"/>
    <parent link="l_palm"/>
    <child link="lhand_base"/>
  </joint>
  <link name="lhand_FingerA">
    <inertial>
      <origin rpy="0 0 0" xyz="0.0141 0.0051 0.0129" />
      <mass value="0.0450000018" />
      <inertia ixx="6.51374875815236E-06" ixy="0" ixz="0" iyy="4.99499947181903E-06" iyz="0" izz="1.78874961420661E-06" />
    </inertial>
    <visual name="FingerA_Visual">
      <geometry>
        <mesh filename="package://robotiq_hand-e/meshes/FingerA.obj" scale="0.01 0.01 0.01" />
      </geometry>
      <material name="lhand_rep_Chrome" />
    </visual>
    <collision name="FingerA_col_1">
      <origin xyz="0.0141 0.0051 0.0129" />
      <geometry>
        <box size="0.006 0.021 0.036" />
      </geometry>
    </collision>
  </link>
  <link name="lhand_FingerB">
    <inertial>
      <origin rpy="0 0 0" xyz="-0.0141 -0.0051 0.0129" />
      <mass value="0.0450000018" />
      <inertia ixx="6.51374875815236E-06" ixy="0" ixz="0" iyy="4.99499947181903E-06" iyz="0" izz="1.78874961420661E-06" />
    </inertial>
    <visual name="FingerB_Visual">
      <geometry>
        <mesh filename="package://robotiq_hand-e/meshes/FingerB.obj" scale="0.01 0.01 0.01" />
      </geometry>
      <material name="lhand_rep_Chrome" />
    </visual>
    <collision name="FingerB_col_1">
      <origin xyz="-0.0141 -0.0051 0.0129" />
      <geometry>
        <box size="0.006 0.021 0.036" />
      </geometry>
    </collision>
  </link>
  <joint name="lhand_fingerA_joint" type="prismatic">
    <origin xyz="0.013914 -0.00523 0.11505" />
    <parent link="lhand_base" />
    <child link="lhand_FingerA" />
    <axis xyz="-1 0 0" />
    <limit lower="0.0" upper="0.025" effort="1000" velocity="1000" />
  </joint>
  <joint name="lhand_fingerB_joint" type="prismatic">
    <origin xyz="-0.013914 0.00523 0.11505" />
    <parent link="lhand_base" />
    <child link="lhand_FingerB" />
    <axis xyz="1 0 0" />
    <limit lower="0.0" upper="0.025" effort="1000" velocity="1000" />
  </joint>
</robot>
