<?xml version="1.0"?>
<sdf version="1.5">
  <model name="eve_r3">
    <link name="pelvis">
      <pose frame="">0 0 0 0 -0 0</pose>
      <inertial>
        <pose frame="">-0.020715 -0.005444 0.410064 0 -0 0</pose>
        <mass>10.1208</mass>
        <inertia>
          <ixx>0.208508</ixx>
          <ixy>0.0008581</ixy>
          <ixz>0.0217618</ixz>
          <iyy>0.208826</iyy>
          <iyz>-0.00715583</iyz>
          <izz>0.0551582</izz>
        </inertia>
      </inertial>
      <visual name="pelvis_visual">
        <pose frame="">0 0 0 1.5708 -0 1.5708</pose>
        <geometry>
          <mesh>
            <scale>1 1 1</scale>
            <uri>model://eve_r3_description/meshes/torso.obj</uri>
          </mesh>
        </geometry>
        
      </visual>
      <gravity>1</gravity>
      <velocity_decay/>
      <sensor name="imu_sensor" type="imu">
        <always_on>1</always_on>
        <update_rate>1000</update_rate>
        <imu>
          <noise>
            <type>gaussian</type>
            <rate>
              <mean>0</mean>
              <stddev>0.0002</stddev>
              <bias_mean>7.5e-06</bias_mean>
              <bias_stddev>8e-07</bias_stddev>
            </rate>
            <accel>
              <mean>0</mean>
              <stddev>0.017</stddev>
              <bias_mean>0.1</bias_mean>
              <bias_stddev>0.001</bias_stddev>
            </accel>
          </noise>
        </imu>
        <pose frame="">0.057 0 0.3979 0 -0 0</pose>
      </sensor>
    </link>
    <link name="abdomen">
      <pose frame="">0 0 0 0 -0 0</pose>
      <inertial>
        <pose frame="">-0.055941 0.001616 0.129607 0 -0 0</pose>
        <mass>3.42955</mass>
        <inertia>
          <ixx>0.055816</ixx>
          <ixy>0.000693</ixy>
          <ixz>-0.014517</ixz>
          <iyy>0.054022</iyy>
          <iyz>-0.001917</iyz>
          <izz>0.020076</izz>
        </inertia>
      </inertial>
      <visual name="abdomen_visual">
        <pose frame="">0 0 0 1.5708 -0 1.5708</pose>
        <geometry>
          <mesh>
            <scale>1 1 1</scale>
            <uri>model://eve_r3_description/meshes/abdomen.obj</uri>
          </mesh>
        </geometry>
      </visual>
    </link>
    <joint name="j_hip_z" type="revolute">
      <child>abdomen</child>
      <parent>pelvis</parent>
      <axis>
        <xyz>0 0 1</xyz>
        <limit>
          <lower>-1.0472</lower>
          <upper>1.0472</upper>
          <effort>-1</effort>
          <velocity>-1</velocity>
        </limit>
        <dynamics>
          <spring_reference>0</spring_reference>
          <spring_stiffness>0</spring_stiffness>
        </dynamics>
        <use_parent_model_frame>1</use_parent_model_frame>
      </axis>
    </joint>
    <link name="hip_x_link">
      <pose frame="">0 0 0 0 -0 0</pose>
      <inertial>
        <pose frame="">-0.013258 -0.001346 -2e-06 0 -0 0</pose>
        <mass>2.9482</mass>
        <inertia>
          <ixx>0.0141892</ixx>
          <ixy>6.936e-05</ixy>
          <ixz>-0.0007734</ixz>
          <iyy>0.0150431</iyy>
          <iyz>1.297e-05</iyz>
          <izz>0.0170189</izz>
        </inertia>
      </inertial>
      <visual name="hip_x_link_visual">
        <pose frame="">0 0 0 1.5708 -0 1.5708</pose>
        <geometry>
          <mesh>
            <scale>1 1 1</scale>
            <uri>model://eve_r3_description/meshes/hip.obj</uri>
          </mesh>
        </geometry>
      </visual>
    </link>
    <joint name="j_hip_x" type="revolute">
      <child>hip_x_link</child>
      <parent>abdomen</parent>
      <axis>
        <xyz>1 0 0</xyz>
        <limit>
          <lower>-0.523599</lower>
          <upper>0.523599</upper>
          <effort>-1</effort>
          <velocity>-1</velocity>
        </limit>
        <dynamics>
          <spring_reference>0</spring_reference>
          <spring_stiffness>0</spring_stiffness>
        </dynamics>
        <use_parent_model_frame>1</use_parent_model_frame>
      </axis>
    </joint>
    <link name="thigh">
      <pose frame="">0 0 0 0 -0 0</pose>
      <inertial>
        <pose frame="">0.042352 0.000173 -0.216898 0 -0 0</pose>
        <mass>10.8088</mass>
        <inertia>
          <ixx>0.16324</ixx>
          <ixy>0.00026721</ixy>
          <ixz>0.0154851</ixz>
          <iyy>0.144919</iyy>
          <iyz>-0.00115905</iyz>
          <izz>0.0665633</izz>
        </inertia>
      </inertial>
      <visual name="thigh_visual">
        <pose frame="">0 0 0 1.5708 -0 1.5708</pose>
        <geometry>
          <mesh>
            <scale>1 1 1</scale>
            <uri>model://eve_r3_description/meshes/thigh.obj</uri>
          </mesh>
        </geometry>
      </visual>
    </link>
    <joint name="j_hip_y" type="revolute">
      <child>thigh</child>
      <parent>hip_x_link</parent>
      <axis>
        <xyz>0 1 0</xyz>
        <limit>
          <lower>-1.57</lower>
          <upper>0.174533</upper>
          <effort>-1</effort>
          <velocity>-1</velocity>
        </limit>
        <dynamics>
          <spring_reference>0</spring_reference>
          <spring_stiffness>0</spring_stiffness>
        </dynamics>
        <use_parent_model_frame>1</use_parent_model_frame>
      </axis>
    </joint>
    <link name="shin">
      <pose frame="">0 0 -0.4 0 -0 0</pose>
      <inertial>
        <pose frame="">0.017742 0.004534 -0.178861 0 -0 0</pose>
        <mass>11.0651</mass>
        <inertia>
          <ixx>0.223006</ixx>
          <ixy>0.00039863</ixy>
          <ixz>0.00421073</ixz>
          <iyy>0.203072</iyy>
          <iyz>0.00715001</iyz>
          <izz>0.0597792</izz>
        </inertia>
      </inertial>
      <visual name="shin_visual">
        <pose frame="">0 0 0 1.5708 -0 1.5708</pose>
        <geometry>
          <mesh>
            <scale>1 1 1</scale>
            <uri>model://eve_r3_description/meshes/shin.obj</uri>
          </mesh>
        </geometry>
      </visual>
    </link>
    <joint name="j_knee_y" type="revolute">
      <child>shin</child>
      <parent>thigh</parent>
      <axis>
        <xyz>0 1 0</xyz>
        <limit>
          <lower>0</lower>
          <upper>2.583</upper>
          <effort>-1</effort>
          <velocity>-1</velocity>
        </limit>
        <dynamics>
          <spring_reference>0</spring_reference>
          <spring_stiffness>0</spring_stiffness>
        </dynamics>
        <use_parent_model_frame>1</use_parent_model_frame>
      </axis>
    </joint>
    <link name="ankle_y_link">
      <pose frame="">0 0 -0.78 0 -0 0</pose>
      <inertial>
        <pose frame="">-0.017472 0.001483 -0.000681 0 -0 0</pose>
        <mass>2.74214</mass>
        <inertia>
          <ixx>0.010787</ixx>
          <ixy>-9e-05</ixy>
          <ixz>0.000271</ixz>
          <iyy>0.009295</iyy>
          <iyz>9e-06</iyz>
          <izz>0.014432</izz>
        </inertia>
      </inertial>
      <visual name="ankle_y_link_visual">
        <pose frame="">0 0 0 1.5708 -0 1.5708</pose>
        <geometry>
          <mesh>
            <scale>1 1 1</scale>
            <uri>model://eve_r3_description/meshes/ankle.obj</uri>
          </mesh>
        </geometry>
      </visual>
    </link>
    <joint name="j_ankle_y" type="revolute">
      <child>ankle_y_link</child>
      <parent>shin</parent>
      <axis>
        <xyz>0 1 0</xyz>
        <limit>
          <lower>-1.57</lower>
          <upper>0.174533</upper>
          <effort>-1</effort>
          <velocity>-1</velocity>
        </limit>
        <dynamics>
          <spring_reference>0</spring_reference>
          <spring_stiffness>0</spring_stiffness>
        </dynamics>
        <use_parent_model_frame>1</use_parent_model_frame>
      </axis>
    </joint>
    <link name="base">
      <pose frame="">0 0 -0.78 0 -0 0</pose>
      <inertial>
        <pose frame="">-0.005001 0.002979 -0.007684 0 -0 0</pose>
        <mass>12.4875</mass>
        <inertia>
          <ixx>0.330887</ixx>
          <ixy>0.005202</ixy>
          <ixz>-0.015354</ixz>
          <iyy>0.233226</iyy>
          <iyz>-3.7e-05</iyz>
          <izz>0.532943</izz>
        </inertia>
      </inertial>
      <collision name="base_collision">
        <pose frame="">-0.284 0 0.019 0 -0 0</pose>
        <geometry>
          <sphere>
            <radius>0.1524</radius>
          </sphere>
        </geometry>
        <surface>
          <contact>
            <ode/>
          </contact>
          <friction>
            <ode>
              <mu>0</mu>
              <mu2>0</mu2>
            </ode>
          </friction>
        </surface>
      </collision>
      <visual name="base_visual">
        <pose frame="">0 0 0 1.5708 -0 1.5708</pose>
        <geometry>
          <mesh>
            <scale>1 1 1</scale>
            <uri>model://eve_r3_description/meshes/base.obj</uri>
          </mesh>
        </geometry>
        
      </visual>
      <gravity>1</gravity>
      <velocity_decay/>
    </link>
    <joint name="j_ankle_x" type="revolute">
      <child>base</child>
      <parent>ankle_y_link</parent>
      <axis>
        <xyz>1 0 0</xyz>
        <limit>
          <lower>-0.523599</lower>
          <upper>0.523599</upper>
          <effort>-1</effort>
          <velocity>-1</velocity>
        </limit>
        <dynamics>
          <spring_reference>0</spring_reference>
          <spring_stiffness>0</spring_stiffness>
        </dynamics>
        <use_parent_model_frame>1</use_parent_model_frame>
      </axis>
    </joint>
    <link name="l_wheel">
      <pose frame="">0.142 0.26983 -0.761 0 -0 0</pose>
      <inertial>
        <pose frame="">1e-06 -0.004876 -0.000141 0 -0 0</pose>
        <mass>2.17851</mass>
        <inertia>
          <ixx>0.0042794</ixx>
          <ixy>-1.22e-06</ixy>
          <ixz>-7.84e-06</ixz>
          <iyy>0.0074513</iyy>
          <iyz>-5.69e-06</iyz>
          <izz>0.00423463</izz>
        </inertia>
      </inertial>
      <collision name="l_wheel_collision">
        <pose frame="">0 0 0 1.5708 -0 0</pose>
        <geometry>
          <cylinder>
            <length>0.03</length>
            <radius>0.1524</radius>
          </cylinder>
        </geometry>
      </collision>
      <visual name="l_wheel_visual">
        <pose frame="">0 0 0 1.5708 0 -1.5708</pose>
        <geometry>
          <mesh>
            <scale>1 1 1</scale>
            <uri>model://eve_r3_description/meshes/wheel.obj</uri>
          </mesh>
        </geometry>
      </visual>
    </link>
    <joint name="j_l_wheel_y" type="revolute">
      <child>l_wheel</child>
      <parent>base</parent>
      <axis>
        <xyz>0 1 0</xyz>
        <limit>
          <lower>-1e+16</lower>
          <upper>1e+16</upper>
        </limit>
        <dynamics>
          <spring_reference>0</spring_reference>
          <spring_stiffness>0</spring_stiffness>
        </dynamics>
        <use_parent_model_frame>1</use_parent_model_frame>
      </axis>
    </joint>
    <link name="r_wheel">
      <pose frame="">0.142 -0.26983 -0.761 0 -0 0</pose>
      <inertial>
        <pose frame="">-1e-06 0.004876 -0.000141 0 -0 0</pose>
        <mass>2.17851</mass>
        <inertia>
          <ixx>0.0042794</ixx>
          <ixy>-1.22e-06</ixy>
          <ixz>7.84e-06</ixz>
          <iyy>0.0074513</iyy>
          <iyz>5.69e-06</iyz>
          <izz>0.00423463</izz>
        </inertia>
      </inertial>
      <collision name="r_wheel_collision">
        <pose frame="">0 0 0 1.5708 -0 0</pose>
        <geometry>
          <cylinder>
            <length>0.03</length>
            <radius>0.1524</radius>
          </cylinder>
        </geometry>
      </collision>
      <visual name="r_wheel_visual">
        <pose frame="">0 0 0 1.5708 -0 1.5708</pose>
        <geometry>
          <mesh>
            <scale>1 1 1</scale>
            <uri>model://eve_r3_description/meshes/wheel.obj</uri>
          </mesh>
        </geometry>
      </visual>
    </link>
    <joint name="j_r_wheel_y" type="revolute">
      <child>r_wheel</child>
      <parent>base</parent>
      <axis>
        <xyz>0 1 0</xyz>
        <limit>
          <lower>-1e+16</lower>
          <upper>1e+16</upper>
        </limit>
        <dynamics>
          <spring_reference>0</spring_reference>
          <spring_stiffness>0</spring_stiffness>
        </dynamics>
        <use_parent_model_frame>1</use_parent_model_frame>
      </axis>
    </joint>
    <link name="l_scapula">
      <pose frame="">0.01041 0.20675 0.54735 0.261799 -0 -0.261799</pose>
      <inertial>
        <pose frame="">0.000511 -0.065347 0.027968 0 -0 0</pose>
        <mass>3.00903</mass>
        <inertia>
          <ixx>0.0102821</ixx>
          <ixy>-4.893e-05</ixy>
          <ixz>-7.063e-05</ixz>
          <iyy>0.0115651</iyy>
          <iyz>-0.00119105</iyz>
          <izz>0.0133308</izz>
        </inertia>
      </inertial>
      <visual name="l_scapula_visual">
        <pose frame="">0 0 0 1.5708 -0 3.14159</pose>
        <geometry>
          <mesh>
            <scale>1 1 1</scale>
            <uri>model://eve_r3_description/meshes/scapula.obj</uri>
          </mesh>
        </geometry>
      </visual>
    </link>
    <joint name="j_l_shoulder_y" type="revolute">
      <child>l_scapula</child>
      <parent>pelvis</parent>
      <axis>
        <xyz>0.25 0.933013 0.258819</xyz>
        <limit>
          <lower>-2.42409</lower>
          <upper>0.98105</upper>
          <effort>-1</effort>
          <velocity>-1</velocity>
        </limit>
        <dynamics>
          <spring_reference>0</spring_reference>
          <spring_stiffness>0</spring_stiffness>
        </dynamics>
        <use_parent_model_frame>1</use_parent_model_frame>
      </axis>
    </joint>
    <link name="l_shoulder">
      <pose frame="">0.01041 0.20675 0.54735 -0 0 -0.261799</pose>
      <inertial>
        <pose frame="">-1.7e-05 0.000194 -0.018711 0 -0 0</pose>
        <mass>0.620918</mass>
        <inertia>
          <ixx>0.00097077</ixx>
          <ixy>3.76e-06</ixy>
          <ixz>-1.39e-06</ixz>
          <iyy>0.00133514</iyy>
          <iyz>5.96e-06</iyz>
          <izz>0.00078248</izz>
        </inertia>
      </inertial>
      <visual name="l_shoulder_visual">
        <pose frame="">0 0 0 3.14159 -0 0</pose>
        <geometry>
          <mesh>
            <scale>1 1 1</scale>
            <uri>model://eve_r3_description/meshes/shoulder.obj</uri>
          </mesh>
        </geometry>
      </visual>
    </link>
    <joint name="j_l_shoulder_x" type="revolute">
      <child>l_shoulder</child>
      <parent>l_scapula</parent>
      <axis>
        <xyz>0.965926 -0.258819 -0</xyz>
        <limit>
          <lower>-0.0872665</lower>
          <upper>2.0944</upper>
          <effort>-1</effort>
          <velocity>-1</velocity>
        </limit>
        <dynamics>
          <spring_reference>0</spring_reference>
          <spring_stiffness>0</spring_stiffness>
        </dynamics>
        <use_parent_model_frame>1</use_parent_model_frame>
      </axis>
    </joint>
    <link name="l_upper_arm">
      <pose frame="">0.01041 0.20675 0.54735 0 0 -0</pose>
      <inertial>
        <pose frame="">-0.006988 0.000111 -0.114991 0 -0 0</pose>
        <mass>3.3226</mass>
        <inertia>
          <ixx>0.0159632</ixx>
          <ixy>8.08e-06</ixy>
          <ixz>-0.00055061</ixz>
          <iyy>0.0155241</iyy>
          <iyz>4.445e-05</iyz>
          <izz>0.00620843</izz>
        </inertia>
      </inertial>
      <visual name="l_upper_arm_visual">
        <pose frame="">0 0 0 1.5708 -0 3.14159</pose>
        <geometry>
          <mesh>
            <scale>1 1 1</scale>
            <uri>model://eve_r3_description/meshes/upper_arm.obj</uri>
          </mesh>
        </geometry>
      </visual>
    </link>
    <joint name="j_l_shoulder_z" type="revolute">
      <child>l_upper_arm</child>
      <parent>l_shoulder</parent>
      <axis>
        <xyz>0 -0 1</xyz>
        <limit>
          <lower>-1.46608</lower>
          <upper>0.541053</upper>
          <effort>-1</effort>
          <velocity>-1</velocity>
        </limit>
        <dynamics>
          <spring_reference>0</spring_reference>
          <spring_stiffness>0</spring_stiffness>
        </dynamics>
        <use_parent_model_frame>1</use_parent_model_frame>
      </axis>
    </joint>
    <link name="l_elbow">
      <pose frame="">0.01041 0.20675 0.23325 0 0 -0</pose>
      <inertial>
        <pose frame="">6.5e-05 2e-06 -0.008906 0 -0 0</pose>
        <mass>0.462285</mass>
        <inertia>
          <ixx>0.0008234</ixx>
          <ixy>-1e-08</ixy>
          <ixz>1.04e-06</ixz>
          <iyy>0.00036507</iyy>
          <iyz>-3e-08</iyz>
          <izz>0.00061458</izz>
        </inertia>
      </inertial>
      <visual name="l_elbow_visual">
        <pose frame="">0 0 0 3.14159 3e-06 -1.5708</pose>
        <geometry>
          <mesh>
            <scale>1 1 1</scale>
            <uri>model://eve_r3_description/meshes/elbow.obj</uri>
          </mesh>
        </geometry>
      </visual>
    </link>
    <joint name="j_l_elbow_y" type="revolute">
      <child>l_elbow</child>
      <parent>l_upper_arm</parent>
      <axis>
        <xyz>0 1 0</xyz>
        <limit>
          <lower>-2.18166</lower>
          <upper>0</upper>
          <effort>-1</effort>
          <velocity>-1</velocity>
        </limit>
        <dynamics>
          <spring_reference>0</spring_reference>
          <spring_stiffness>0</spring_stiffness>
        </dynamics>
        <use_parent_model_frame>1</use_parent_model_frame>
      </axis>
    </joint>
    <link name="l_lower_arm">
      <pose frame="">0.01041 0.20675 0.23325 0 0 -0</pose>
      <inertial>
        <pose frame="">5.2e-05 -6e-05 -0.142724 0 -0 0</pose>
        <mass>1.72647</mass>
        <inertia>
          <ixx>0.00752577</ixx>
          <ixy>3.09e-06</ixy>
          <ixz>-3.88e-06</ixz>
          <iyy>0.0078581</iyy>
          <iyz>-4.25e-06</iyz>
          <izz>0.00189705</izz>
        </inertia>
      </inertial>
      <visual name="l_lower_arm_visual">
        <pose frame="">0 0 -0.29285 3.14159 3e-06 3.14159</pose>
        <geometry>
          <mesh>
            <scale>1 1 1</scale>
            <uri>model://eve_r3_description/meshes/forearm.obj</uri>
          </mesh>
        </geometry>
      </visual>
    </link>
    <joint name="j_l_elbow_z" type="revolute">
      <child>l_lower_arm</child>
      <parent>l_elbow</parent>
      <axis>
        <xyz>0 -0 1</xyz>
        <limit>
          <lower>-1.5708</lower>
          <upper>0.7854</upper>
          <effort>-1</effort>
          <velocity>-1</velocity>
        </limit>
        <dynamics>
          <spring_reference>0</spring_reference>
          <spring_stiffness>0</spring_stiffness>
        </dynamics>
        <use_parent_model_frame>1</use_parent_model_frame>
      </axis>
    </joint>
    <link name="l_wrist">
      <pose frame="">0.01041 0.20675 -0.0596 0 0 -0</pose>
      <inertial>
        <pose frame="">-0.000186 -5.5e-05 -0.001294 0 -0 0</pose>
        <mass>0.358205</mass>
        <inertia>
          <ixx>0.0002896</ixx>
          <ixy>2.1e-06</ixy>
          <ixz>1.1e-06</ixz>
          <iyy>0.0002335</iyy>
          <iyz>3e-07</iyz>
          <izz>0.0003221</izz>
        </inertia>
      </inertial>
      <visual name="l_wrist_visual">
        <pose frame="">0 0 0 0 -0 1.5708</pose>
        <geometry>
          <mesh>
            <scale>1 1 1</scale>
            <uri>model://eve_r3_description/meshes/wrist.obj</uri>
          </mesh>
        </geometry>
      </visual>
    </link>
    <joint name="j_l_wrist_y" type="revolute">
      <child>l_wrist</child>
      <parent>l_lower_arm</parent>
      <axis>
        <xyz>0 1 0</xyz>
        <limit>
          <lower>-0.785398</lower>
          <upper>0.785398</upper>
          <effort>-1</effort>
          <velocity>-1</velocity>
        </limit>
        <dynamics>
          <spring_reference>0</spring_reference>
          <spring_stiffness>0</spring_stiffness>
        </dynamics>
        <use_parent_model_frame>1</use_parent_model_frame>
      </axis>
    </joint>
    <link name="l_palm">
      <pose frame="">0.01041 0.20675 -0.0596 0 0 -0</pose>
      <inertial>
        <pose frame="">0.002324 -0.025861 -0.14918 0 -0 0</pose>
        <mass>0.905292</mass>
        <inertia>
          <ixx>0.00894307</ixx>
          <ixy>8.65457e-05</ixy>
          <ixz>0.00022098</ixz>
          <iyy>0.00825902</iyy>
          <iyz>-0.00181678</iyz>
          <izz>0.00215822</izz>
        </inertia>
      </inertial>
      <collision name="l_palm_fixed_joint_lump__qbhand_left_base_link_collision">
        <pose frame="">0 0 -0.06 3.14 -0 0</pose>
        <geometry>
          <mesh>
            <scale>0.001 0.001 0.001</scale>
            <uri>model://qb_hand_description/meshes/flange_iso_04.stl</uri>
          </mesh>
        </geometry>
      </collision>
      <collision name="l_palm_fixed_joint_lump__qbhand_left_palm_link_collision_1">
        <pose frame="">0.0045 -0.014729 -0.203977 -1.57 -3e-06 -3.14</pose>
        <geometry>
          <mesh>
            <scale>0.001 0.001 0.001</scale>
            <uri>model://qb_hand_description/meshes/palm_pinch_l.stl</uri>
          </mesh>
        </geometry>
      </collision>
      <collision name="l_palm_fixed_joint_lump__qbhand_left_index_knuckle_link_collision_2">
        <pose frame="">0.024478 -0.000692 -0.196988 -1.57159 4e-06 0.003185</pose>
        <geometry>
          <mesh>
            <scale>0.001 0.001 0.001</scale>
            <uri>model://qb_hand_description/meshes/ph_knuckle.stl</uri>
          </mesh>
        </geometry>
      </collision>
      <collision name="l_palm_fixed_joint_lump__qbhand_left_index_proximal_link_collision_3">
        <pose frame="">0.024488 -0.000709 -0.218988 3.14159 1.57079 -3.13681</pose>
        <geometry>
          <mesh>
            <scale>0.001 0.001 0.001</scale>
            <uri>model://qb_hand_description/meshes/ph_medium.stl</uri>
          </mesh>
        </geometry>
      </collision>
      <collision name="l_palm_fixed_joint_lump__qbhand_left_index_middle_link_collision_4">
        <pose frame="">0.024512 -0.000733 -0.248988 3.14159 1.57079 -3.13681</pose>
        <geometry>
          <mesh>
            <scale>0.001 0.001 0.001</scale>
            <uri>model://qb_hand_description/meshes/ph_small.stl</uri>
          </mesh>
        </geometry>
      </collision>
      <collision name="l_palm_fixed_joint_lump__qbhand_left_index_distal_link_collision_5">
        <pose frame="">0.024529 -0.000751 -0.270988 3.14159 1.57079 -3.13681</pose>
        <geometry>
          <mesh>
            <scale>0.001 0.001 0.001</scale>
            <uri>model://qb_hand_description/meshes/ph_distal.stl</uri>
          </mesh>
        </geometry>
      </collision>
      <collision name="l_palm_fixed_joint_lump__qbhand_left_little_knuckle_link_collision_6">
        <pose frame="">-0.035522 -0.000783 -0.191988 -1.57159 4e-06 0.003185</pose>
        <geometry>
          <mesh>
            <scale>0.001 0.001 0.001</scale>
            <uri>model://qb_hand_description/meshes/ph_knuckle.stl</uri>
          </mesh>
        </geometry>
      </collision>
      <collision name="l_palm_fixed_joint_lump__qbhand_left_little_proximal_link_collision_7">
        <pose frame="">-0.035512 -0.000801 -0.213988 3.14159 1.57079 -3.13681</pose>
        <geometry>
          <mesh>
            <scale>0.001 0.001 0.001</scale>
            <uri>model://qb_hand_description/meshes/ph_small.stl</uri>
          </mesh>
        </geometry>
      </collision>
      <collision name="l_palm_fixed_joint_lump__qbhand_left_little_middle_link_collision_8">
        <pose frame="">-0.035494 -0.000818 -0.235988 3.14159 1.57079 -3.13681</pose>
        <geometry>
          <mesh>
            <scale>0.001 0.001 0.001</scale>
            <uri>model://qb_hand_description/meshes/ph_small.stl</uri>
          </mesh>
        </geometry>
      </collision>
      <collision name="l_palm_fixed_joint_lump__qbhand_left_little_distal_link_collision_9">
        <pose frame="">-0.035477 -0.000836 -0.257988 3.14159 1.57079 -3.13681</pose>
        <geometry>
          <mesh>
            <scale>0.001 0.001 0.001</scale>
            <uri>model://qb_hand_description/meshes/ph_distal.stl</uri>
          </mesh>
        </geometry>
      </collision>
      <collision name="l_palm_fixed_joint_lump__qbhand_left_middle_knuckle_link_collision_10">
        <pose frame="">0.004478 -0.000729 -0.203988 -1.57159 4e-06 0.003185</pose>
        <geometry>
          <mesh>
            <scale>0.001 0.001 0.001</scale>
            <uri>model://qb_hand_description/meshes/ph_knuckle.stl</uri>
          </mesh>
        </geometry>
      </collision>
      <collision name="l_palm_fixed_joint_lump__qbhand_left_middle_proximal_link_collision_11">
        <pose frame="">0.004488 -0.000747 -0.225988 3.14159 1.57079 -3.13681</pose>
        <geometry>
          <mesh>
            <scale>0.001 0.001 0.001</scale>
            <uri>model://qb_hand_description/meshes/ph_medium.stl</uri>
          </mesh>
        </geometry>
      </collision>
      <collision name="l_palm_fixed_joint_lump__qbhand_left_middle_middle_link_collision_12">
        <pose frame="">0.004512 -0.000771 -0.255988 3.14159 1.57079 -3.13681</pose>
        <geometry>
          <mesh>
            <scale>0.001 0.001 0.001</scale>
            <uri>model://qb_hand_description/meshes/ph_small.stl</uri>
          </mesh>
        </geometry>
      </collision>
      <collision name="l_palm_fixed_joint_lump__qbhand_left_middle_distal_link_collision_13">
        <pose frame="">0.004529 -0.000788 -0.277988 3.14159 1.57079 -3.13681</pose>
        <geometry>
          <mesh>
            <scale>0.001 0.001 0.001</scale>
            <uri>model://qb_hand_description/meshes/ph_distal.stl</uri>
          </mesh>
        </geometry>
      </collision>
      <collision name="l_palm_fixed_joint_lump__qbhand_left_ring_knuckle_link_collision_14">
        <pose frame="">-0.015522 -0.000756 -0.196988 -1.57159 4e-06 0.003185</pose>
        <geometry>
          <mesh>
            <scale>0.001 0.001 0.001</scale>
            <uri>model://qb_hand_description/meshes/ph_knuckle.stl</uri>
          </mesh>
        </geometry>
      </collision>
      <collision name="l_palm_fixed_joint_lump__qbhand_left_ring_proximal_link_collision_15">
        <pose frame="">-0.015512 -0.000773 -0.218988 3.14159 1.57079 -3.13681</pose>
        <geometry>
          <mesh>
            <scale>0.001 0.001 0.001</scale>
            <uri>model://qb_hand_description/meshes/ph_medium.stl</uri>
          </mesh>
        </geometry>
      </collision>
      <collision name="l_palm_fixed_joint_lump__qbhand_left_ring_middle_link_collision_16">
        <pose frame="">-0.015488 -0.000797 -0.248988 3.14159 1.57079 -3.13681</pose>
        <geometry>
          <mesh>
            <scale>0.001 0.001 0.001</scale>
            <uri>model://qb_hand_description/meshes/ph_small.stl</uri>
          </mesh>
        </geometry>
      </collision>
      <collision name="l_palm_fixed_joint_lump__qbhand_left_ring_distal_link_collision_17">
        <pose frame="">-0.015471 -0.000814 -0.270988 3.14159 1.57079 -3.13681</pose>
        <geometry>
          <mesh>
            <scale>0.001 0.001 0.001</scale>
            <uri>model://qb_hand_description/meshes/ph_distal.stl</uri>
          </mesh>
        </geometry>
      </collision>
      <collision name="l_palm_fixed_joint_lump__qbhand_left_thumb_knuckle_link_collision_18">
        <pose frame="">0.047997 -0.012625 -0.160478 -0.001593 4e-06 0.003185</pose>
        <geometry>
          <mesh>
            <scale>0.001 0.001 0.001</scale>
            <uri>model://qb_hand_description/meshes/ph_thumb_l.stl</uri>
          </mesh>
        </geometry>
      </collision>
      <collision name="l_palm_fixed_joint_lump__qbhand_left_thumb_proximal_link_collision_19">
        <pose frame="">0.086509 -0.016499 -0.157972 1.14841 4e-06 0.003185</pose>
        <geometry>
          <mesh>
            <scale>0.001 0.001 0.001</scale>
            <uri>model://qb_hand_description/meshes/ph_small.stl</uri>
          </mesh>
        </geometry>
      </collision>
      <collision name="l_palm_fixed_joint_lump__qbhand_left_thumb_distal_link_collision_20">
        <pose frame="">0.108509 -0.016429 -0.157972 1.14841 4e-06 0.003185</pose>
        <geometry>
          <mesh>
            <scale>0.001 0.001 0.001</scale>
            <uri>model://qb_hand_description/meshes/ph_distal.stl</uri>
          </mesh>
        </geometry>
      </collision>
      <visual name="l_palm_visual">
        <pose frame="">0 0 0 -1.5708 -0 3.14159</pose>
        <geometry>
          <mesh>
            <scale>1 1 1</scale>
            <uri>model://eve_r3_description/meshes/palm.obj</uri>
          </mesh>
        </geometry>
      </visual>
      <visual name="l_palm_fixed_joint_lump__qbhand_left_base_link_visual_1">
        <pose frame="">0 0 -0.06 3.14 -0 0</pose>
        <geometry>
          <mesh>
            <scale>0.001 0.001 0.001</scale>
            <uri>model://qb_hand_description/meshes/flange_iso_04.stl</uri>
          </mesh>
        </geometry>
      </visual>
      <visual name="l_palm_fixed_joint_lump__qbhand_left_palm_link_visual_2">
        <pose frame="">0.0045 -0.014729 -0.203977 -1.57 -3e-06 -3.14</pose>
        <geometry>
          <mesh>
            <scale>0.001 0.001 0.001</scale>
            <uri>model://qb_hand_description/meshes/palm_pinch_l.stl</uri>
          </mesh>
        </geometry>
      </visual>
      <visual name="l_palm_fixed_joint_lump__qbhand_left_index_knuckle_link_visual_3">
        <pose frame="">0.024478 -0.000692 -0.196988 -1.57159 4e-06 0.003185</pose>
        <geometry>
          <mesh>
            <scale>0.001 0.001 0.001</scale>
            <uri>model://qb_hand_description/meshes/ph_knuckle.stl</uri>
          </mesh>
        </geometry>
      </visual>
      <visual name="l_palm_fixed_joint_lump__qbhand_left_index_proximal_link_visual_4">
        <pose frame="">0.024488 -0.000709 -0.218988 3.14159 1.57079 -3.13681</pose>
        <geometry>
          <mesh>
            <scale>0.001 0.001 0.001</scale>
            <uri>model://qb_hand_description/meshes/ph_medium.stl</uri>
          </mesh>
        </geometry>
      </visual>
      <visual name="l_palm_fixed_joint_lump__qbhand_left_index_middle_link_visual_5">
        <pose frame="">0.024512 -0.000733 -0.248988 3.14159 1.57079 -3.13681</pose>
        <geometry>
          <mesh>
            <scale>0.001 0.001 0.001</scale>
            <uri>model://qb_hand_description/meshes/ph_small.stl</uri>
          </mesh>
        </geometry>
      </visual>
      <visual name="l_palm_fixed_joint_lump__qbhand_left_index_distal_link_visual_6">
        <pose frame="">0.024529 -0.000751 -0.270988 3.14159 1.57079 -3.13681</pose>
        <geometry>
          <mesh>
            <scale>0.001 0.001 0.001</scale>
            <uri>model://qb_hand_description/meshes/ph_distal.stl</uri>
          </mesh>
        </geometry>
      </visual>
      <visual name="l_palm_fixed_joint_lump__qbhand_left_little_knuckle_link_visual_7">
        <pose frame="">-0.035522 -0.000783 -0.191988 -1.57159 4e-06 0.003185</pose>
        <geometry>
          <mesh>
            <scale>0.001 0.001 0.001</scale>
            <uri>model://qb_hand_description/meshes/ph_knuckle.stl</uri>
          </mesh>
        </geometry>
      </visual>
      <visual name="l_palm_fixed_joint_lump__qbhand_left_little_proximal_link_visual_8">
        <pose frame="">-0.035512 -0.000801 -0.213988 3.14159 1.57079 -3.13681</pose>
        <geometry>
          <mesh>
            <scale>0.001 0.001 0.001</scale>
            <uri>model://qb_hand_description/meshes/ph_small.stl</uri>
          </mesh>
        </geometry>
      </visual>
      <visual name="l_palm_fixed_joint_lump__qbhand_left_little_middle_link_visual_9">
        <pose frame="">-0.035494 -0.000818 -0.235988 3.14159 1.57079 -3.13681</pose>
        <geometry>
          <mesh>
            <scale>0.001 0.001 0.001</scale>
            <uri>model://qb_hand_description/meshes/ph_small.stl</uri>
          </mesh>
        </geometry>
      </visual>
      <visual name="l_palm_fixed_joint_lump__qbhand_left_little_distal_link_visual_10">
        <pose frame="">-0.035477 -0.000836 -0.257988 3.14159 1.57079 -3.13681</pose>
        <geometry>
          <mesh>
            <scale>0.001 0.001 0.001</scale>
            <uri>model://qb_hand_description/meshes/ph_distal.stl</uri>
          </mesh>
        </geometry>
      </visual>
      <visual name="l_palm_fixed_joint_lump__qbhand_left_middle_knuckle_link_visual_11">
        <pose frame="">0.004478 -0.000729 -0.203988 -1.57159 4e-06 0.003185</pose>
        <geometry>
          <mesh>
            <scale>0.001 0.001 0.001</scale>
            <uri>model://qb_hand_description/meshes/ph_knuckle.stl</uri>
          </mesh>
        </geometry>
      </visual>
      <visual name="l_palm_fixed_joint_lump__qbhand_left_middle_proximal_link_visual_12">
        <pose frame="">0.004488 -0.000747 -0.225988 3.14159 1.57079 -3.13681</pose>
        <geometry>
          <mesh>
            <scale>0.001 0.001 0.001</scale>
            <uri>model://qb_hand_description/meshes/ph_medium.stl</uri>
          </mesh>
        </geometry>
      </visual>
      <visual name="l_palm_fixed_joint_lump__qbhand_left_middle_middle_link_visual_13">
        <pose frame="">0.004512 -0.000771 -0.255988 3.14159 1.57079 -3.13681</pose>
        <geometry>
          <mesh>
            <scale>0.001 0.001 0.001</scale>
            <uri>model://qb_hand_description/meshes/ph_small.stl</uri>
          </mesh>
        </geometry>
      </visual>
      <visual name="l_palm_fixed_joint_lump__qbhand_left_middle_distal_link_visual_14">
        <pose frame="">0.004529 -0.000788 -0.277988 3.14159 1.57079 -3.13681</pose>
        <geometry>
          <mesh>
            <scale>0.001 0.001 0.001</scale>
            <uri>model://qb_hand_description/meshes/ph_distal.stl</uri>
          </mesh>
        </geometry>
      </visual>
      <visual name="l_palm_fixed_joint_lump__qbhand_left_ring_knuckle_link_visual_15">
        <pose frame="">-0.015522 -0.000756 -0.196988 -1.57159 4e-06 0.003185</pose>
        <geometry>
          <mesh>
            <scale>0.001 0.001 0.001</scale>
            <uri>model://qb_hand_description/meshes/ph_knuckle.stl</uri>
          </mesh>
        </geometry>
      </visual>
      <visual name="l_palm_fixed_joint_lump__qbhand_left_ring_proximal_link_visual_16">
        <pose frame="">-0.015512 -0.000773 -0.218988 3.14159 1.57079 -3.13681</pose>
        <geometry>
          <mesh>
            <scale>0.001 0.001 0.001</scale>
            <uri>model://qb_hand_description/meshes/ph_medium.stl</uri>
          </mesh>
        </geometry>
      </visual>
      <visual name="l_palm_fixed_joint_lump__qbhand_left_ring_middle_link_visual_17">
        <pose frame="">-0.015488 -0.000797 -0.248988 3.14159 1.57079 -3.13681</pose>
        <geometry>
          <mesh>
            <scale>0.001 0.001 0.001</scale>
            <uri>model://qb_hand_description/meshes/ph_small.stl</uri>
          </mesh>
        </geometry>
      </visual>
      <visual name="l_palm_fixed_joint_lump__qbhand_left_ring_distal_link_visual_18">
        <pose frame="">-0.015471 -0.000814 -0.270988 3.14159 1.57079 -3.13681</pose>
        <geometry>
          <mesh>
            <scale>0.001 0.001 0.001</scale>
            <uri>model://qb_hand_description/meshes/ph_distal.stl</uri>
          </mesh>
        </geometry>
      </visual>
      <visual name="l_palm_fixed_joint_lump__qbhand_left_thumb_knuckle_link_visual_19">
        <pose frame="">0.047997 -0.012625 -0.160478 -0.001593 4e-06 0.003185</pose>
        <geometry>
          <mesh>
            <scale>0.001 0.001 0.001</scale>
            <uri>model://qb_hand_description/meshes/ph_thumb_l.stl</uri>
          </mesh>
        </geometry>
      </visual>
      <visual name="l_palm_fixed_joint_lump__qbhand_left_thumb_proximal_link_visual_20">
        <pose frame="">0.086509 -0.016499 -0.157972 1.14841 4e-06 0.003185</pose>
        <geometry>
          <mesh>
            <scale>0.001 0.001 0.001</scale>
            <uri>model://qb_hand_description/meshes/ph_small.stl</uri>
          </mesh>
        </geometry>
      </visual>
      <visual name="l_palm_fixed_joint_lump__qbhand_left_thumb_distal_link_visual_21">
        <pose frame="">0.108509 -0.016429 -0.157972 1.14841 4e-06 0.003185</pose>
        <geometry>
          <mesh>
            <scale>0.001 0.001 0.001</scale>
            <uri>model://qb_hand_description/meshes/ph_distal.stl</uri>
          </mesh>
        </geometry>
      </visual>
    </link>
    <joint name="j_l_wrist_x" type="revolute">
      <child>l_palm</child>
      <parent>l_wrist</parent>
      <axis>
        <xyz>1 -0 -0</xyz>
        <limit>
          <lower>-1.5708</lower>
          <upper>0.523599</upper>
          <effort>-1</effort>
          <velocity>-1</velocity>
        </limit>
        <dynamics>
          <spring_reference>0</spring_reference>
          <spring_stiffness>0</spring_stiffness>
        </dynamics>
        <use_parent_model_frame>1</use_parent_model_frame>
      </axis>
    </joint>
    <link name="head">
      <pose frame="">0.00646 0.00085 0.67201 0 -0 0</pose>
      <inertial>
        <pose frame="">0.02486 -0.003732 0.11158 0 -0 0</pose>
        <mass>1.84976</mass>
        <inertia>
          <ixx>0.0134363</ixx>
          <ixy>-0.00015664</ixy>
          <ixz>-0.00146014</ixz>
          <iyy>0.0151726</iyy>
          <iyz>0.00017375</iyz>
          <izz>0.00763704</izz>
        </inertia>
      </inertial>
      <visual name="head_visual">
        <pose frame="">0 0 0 1.5708 -0 1.5708</pose>
        <geometry>
          <mesh>
            <scale>1 1 1</scale>
            <uri>model://eve_r3_description/meshes/head.obj</uri>
          </mesh>
        </geometry>
        
      </visual>
      <gravity>1</gravity>
      <velocity_decay/>
      <sensor name="realsense" type="camera">
        <camera name="__default__">
          <image>
            <width>640</width>
            <height>480</height>
            <format>R8G8B8</format>
          </image>
          <horizontal_fov>1.48702</horizontal_fov>
          <clip>
            <near>0.2</near>
            <far>10</far>
          </clip>
        </camera>
        <update_rate>6</update_rate>
        <pose frame="">0.116669 0 0.17015 0 0.174533 0</pose>
      </sensor>
    </link>
    <joint name="j_neck_y" type="revolute">
      <child>head</child>
      <parent>pelvis</parent>
      <axis>
        <xyz>0 1 0</xyz>
        <limit>
          <lower>-0.0872665</lower>
          <upper>0.698132</upper>
          <effort>-1</effort>
          <velocity>-1</velocity>
        </limit>
        <dynamics>
          <spring_reference>0</spring_reference>
          <spring_stiffness>0</spring_stiffness>
        </dynamics>
        <use_parent_model_frame>1</use_parent_model_frame>
      </axis>
    </joint>
    <link name="r_scapula">
      <pose frame="">0.01041 -0.20675 0.54735 -0.261799 -0 0.261799</pose>
      <inertial>
        <pose frame="">0.000379 0.065183 0.028165 0 -0 0</pose>
        <mass>3.0022</mass>
        <inertia>
          <ixx>0.0102071</ixx>
          <ixy>2.03e-06</ixy>
          <ixz>-3.444e-05</ixz>
          <iyy>0.0115173</iyy>
          <iyz>0.00114803</iyz>
          <izz>0.0132945</izz>
        </inertia>
      </inertial>
      <visual name="r_scapula_visual">
        <pose frame="">0 0 0 1.5708 -0 0</pose>
        <geometry>
          <mesh>
            <scale>1 1 1</scale>
            <uri>model://eve_r3_description/meshes/scapula.obj</uri>
          </mesh>
        </geometry>
      </visual>
    </link>
    <joint name="j_r_shoulder_y" type="revolute">
      <child>r_scapula</child>
      <parent>pelvis</parent>
      <axis>
        <xyz>-0.25 0.933013 -0.258819</xyz>
        <limit>
          <lower>-2.42409</lower>
          <upper>0.98105</upper>
          <effort>-1</effort>
          <velocity>-1</velocity>
        </limit>
        <dynamics>
          <spring_reference>0</spring_reference>
          <spring_stiffness>0</spring_stiffness>
        </dynamics>
        <use_parent_model_frame>1</use_parent_model_frame>
      </axis>
    </joint>
    <link name="r_shoulder">
      <pose frame="">0.01041 -0.20675 0.54735 0 0 0.261799</pose>
      <inertial>
        <pose frame="">1.7e-05 -0.000194 -0.018711 0 -0 0</pose>
        <mass>0.620918</mass>
        <inertia>
          <ixx>0.00097077</ixx>
          <ixy>3.76e-06</ixy>
          <ixz>1.39e-06</ixz>
          <iyy>0.00133514</iyy>
          <iyz>-5.96e-06</iyz>
          <izz>0.00078248</izz>
        </inertia>
      </inertial>
      <visual name="r_shoulder_visual">
        <pose frame="">0 0 0 3.14159 -0 0</pose>
        <geometry>
          <mesh>
            <scale>1 1 1</scale>
            <uri>model://eve_r3_description/meshes/shoulder.obj</uri>
          </mesh>
        </geometry>
      </visual>
    </link>
    <joint name="j_r_shoulder_x" type="revolute">
      <child>r_shoulder</child>
      <parent>r_scapula</parent>
      <axis>
        <xyz>0.965926 0.258819 -0</xyz>
        <limit>
          <lower>-2.0944</lower>
          <upper>0.0872665</upper>
          <effort>-1</effort>
          <velocity>-1</velocity>
        </limit>
        <dynamics>
          <spring_reference>0</spring_reference>
          <spring_stiffness>0</spring_stiffness>
        </dynamics>
        <use_parent_model_frame>1</use_parent_model_frame>
      </axis>
    </joint>
    <link name="r_upper_arm">
      <pose frame="">0.01041 -0.20675 0.54735 -0 0 0</pose>
      <inertial>
        <pose frame="">-0.006997 0.000138 -0.174067 0 -0 0</pose>
        <mass>3.32084</mass>
        <inertia>
          <ixx>0.0159415</ixx>
          <ixy>8.55e-06</ixy>
          <ixz>-0.00054922</ixz>
          <iyy>0.0155058</iyy>
          <iyz>3.617e-05</iyz>
          <izz>0.00620232</izz>
        </inertia>
      </inertial>
      <visual name="r_upper_arm_visual">
        <pose frame="">0 0 0 1.5708 -0 3.14159</pose>
        <geometry>
          <mesh>
            <scale>1 1 1</scale>
            <uri>model://eve_r3_description/meshes/upper_arm.obj</uri>
          </mesh>
        </geometry>
      </visual>
    </link>
    <joint name="j_r_shoulder_z" type="revolute">
      <child>r_upper_arm</child>
      <parent>r_shoulder</parent>
      <axis>
        <xyz>0 0 1</xyz>
        <limit>
          <lower>-0.541053</lower>
          <upper>1.46608</upper>
          <effort>-1</effort>
          <velocity>-1</velocity>
        </limit>
        <dynamics>
          <spring_reference>0</spring_reference>
          <spring_stiffness>0</spring_stiffness>
        </dynamics>
        <use_parent_model_frame>1</use_parent_model_frame>
      </axis>
    </joint>
    <link name="r_elbow">
      <pose frame="">0.01041 -0.20675 0.23325 -0 0 0</pose>
      <inertial>
        <pose frame="">6.6e-05 2e-06 -0.008906 0 -0 0</pose>
        <mass>0.462289</mass>
        <inertia>
          <ixx>0.0008234</ixx>
          <ixy>-2e-08</ixy>
          <ixz>1.04e-06</ixz>
          <iyy>0.00036507</iyy>
          <iyz>-3e-08</iyz>
          <izz>0.00061458</izz>
        </inertia>
      </inertial>
      <visual name="r_elbow_visual">
        <pose frame="">0 0 0 3.14159 3e-06 -1.5708</pose>
        <geometry>
          <mesh>
            <scale>1 1 1</scale>
            <uri>model://eve_r3_description/meshes/elbow.obj</uri>
          </mesh>
        </geometry>
      </visual>
    </link>
    <joint name="j_r_elbow_y" type="revolute">
      <child>r_elbow</child>
      <parent>r_upper_arm</parent>
      <axis>
        <xyz>-0 1 -0</xyz>
        <limit>
          <lower>-2.18166</lower>
          <upper>0</upper>
          <effort>-1</effort>
          <velocity>-1</velocity>
        </limit>
        <dynamics>
          <spring_reference>0</spring_reference>
          <spring_stiffness>0</spring_stiffness>
        </dynamics>
        <use_parent_model_frame>1</use_parent_model_frame>
      </axis>
    </joint>
    <link name="r_lower_arm">
      <pose frame="">0.01041 -0.20675 0.23325 -0 0 0</pose>
      <inertial>
        <pose frame="">4.9e-05 -7.6e-05 -0.142725 0 -0 0</pose>
        <mass>1.72645</mass>
        <inertia>
          <ixx>0.00752527</ixx>
          <ixy>2.55e-06</ixy>
          <ixz>-3.2e-06</ixz>
          <iyy>0.00785805</iyy>
          <iyz>-8.5e-07</iyz>
          <izz>0.00189704</izz>
        </inertia>
      </inertial>
      <visual name="r_lower_arm_visual">
        <pose frame="">0 0 -0.29285 3.14159 3e-06 3.14159</pose>
        <geometry>
          <mesh>
            <scale>1 1 1</scale>
            <uri>model://eve_r3_description/meshes/forearm.obj</uri>
          </mesh>
        </geometry>
      </visual>
    </link>
    <joint name="j_r_elbow_z" type="revolute">
      <child>r_lower_arm</child>
      <parent>r_elbow</parent>
      <axis>
        <xyz>0 0 1</xyz>
        <limit>
          <lower>-0.7854</lower>
          <upper>1.5708</upper>
          <effort>-1</effort>
          <velocity>-1</velocity>
        </limit>
        <dynamics>
          <spring_reference>0</spring_reference>
          <spring_stiffness>0</spring_stiffness>
        </dynamics>
        <use_parent_model_frame>1</use_parent_model_frame>
      </axis>
    </joint>
    <link name="r_wrist">
      <pose frame="">0.01041 -0.20675 -0.0596 -0 0 0</pose>
      <inertial>
        <pose frame="">0.000186 5.5e-05 -0.001294 0 -0 0</pose>
        <mass>0.358205</mass>
        <inertia>
          <ixx>0.0002896</ixx>
          <ixy>2.1e-06</ixy>
          <ixz>-1.1e-06</ixz>
          <iyy>0.0002335</iyy>
          <iyz>-3e-07</iyz>
          <izz>0.0003221</izz>
        </inertia>
      </inertial>
      <visual name="r_wrist_visual">
        <pose frame="">0 0 0 0 -0 1.5708</pose>
        <geometry>
          <mesh>
            <scale>1 1 1</scale>
            <uri>model://eve_r3_description/meshes/wrist.obj</uri>
          </mesh>
        </geometry>
      </visual>
    </link>
    <joint name="j_r_wrist_y" type="revolute">
      <child>r_wrist</child>
      <parent>r_lower_arm</parent>
      <axis>
        <xyz>-0 1 -0</xyz>
        <limit>
          <lower>-0.785398</lower>
          <upper>0.785398</upper>
          <effort>-1</effort>
          <velocity>-1</velocity>
        </limit>
        <dynamics>
          <spring_reference>0</spring_reference>
          <spring_stiffness>0</spring_stiffness>
        </dynamics>
        <use_parent_model_frame>1</use_parent_model_frame>
      </axis>
    </joint>
    <link name="r_palm">
      <pose frame="">0.01041 -0.20675 -0.0596 -0 0 0</pose>
      <inertial>
        <pose frame="">0.004162 -0.013778 -0.149246 0 -0 0</pose>
        <mass>0.905292</mass>
        <inertia>
          <ixx>0.00832704</ixx>
          <ixy>-3.56302e-05</ixy>
          <ixz>-4.26885e-05</ixz>
          <iyy>0.00825697</iyy>
          <iyz>-0.000874007</iyz>
          <izz>0.00152197</izz>
        </inertia>
      </inertial>
      <collision name="r_palm_fixed_joint_lump__qbhand_right_base_link_collision">
        <pose frame="">0 0 -0.06 3.14 -0 3.14</pose>
        <geometry>
          <mesh>
            <scale>0.001 0.001 0.001</scale>
            <uri>model://qb_hand_description/meshes/flange_iso_04.stl</uri>
          </mesh>
        </geometry>
      </collision>
      <collision name="r_palm_fixed_joint_lump__qbhand_right_palm_link_collision_1">
        <pose frame="">0.004523 0.014722 -0.203977 -1.57319 -0 3.14</pose>
        <geometry>
          <mesh>
            <scale>0.001 0.001 0.001</scale>
            <uri>model://qb_hand_description/meshes/palm_pinch_r.stl</uri>
          </mesh>
        </geometry>
      </collision>
      <collision name="r_palm_fixed_joint_lump__qbhand_right_index_knuckle_link_collision_2">
        <pose frame="">0.024501 0.000674 -0.19701 -1.57319 -0 3.14</pose>
        <geometry>
          <mesh>
            <scale>0.001 0.001 0.001</scale>
            <uri>model://qb_hand_description/meshes/ph_knuckle.stl</uri>
          </mesh>
        </geometry>
      </collision>
      <collision name="r_palm_fixed_joint_lump__qbhand_right_index_proximal_link_collision_3">
        <pose frame="">0.024491 0.000726 -0.21901 3.14159 1.57079 0.001593</pose>
        <geometry>
          <mesh>
            <scale>0.001 0.001 0.001</scale>
            <uri>model://qb_hand_description/meshes/ph_medium.stl</uri>
          </mesh>
        </geometry>
      </collision>
      <collision name="r_palm_fixed_joint_lump__qbhand_right_index_middle_link_collision_4">
        <pose frame="">0.024467 0.000798 -0.24901 3.14159 1.57079 0.001593</pose>
        <geometry>
          <mesh>
            <scale>0.001 0.001 0.001</scale>
            <uri>model://qb_hand_description/meshes/ph_small.stl</uri>
          </mesh>
        </geometry>
      </collision>
      <collision name="r_palm_fixed_joint_lump__qbhand_right_index_distal_link_collision_5">
        <pose frame="">0.02445 0.00085 -0.27101 3.14159 1.57079 0.001593</pose>
        <geometry>
          <mesh>
            <scale>0.001 0.001 0.001</scale>
            <uri>model://qb_hand_description/meshes/ph_distal.stl</uri>
          </mesh>
        </geometry>
      </collision>
      <collision name="r_palm_fixed_joint_lump__qbhand_right_little_knuckle_link_collision_6">
        <pose frame="">-0.035499 0.000757 -0.19201 -1.57319 -0 3.14</pose>
        <geometry>
          <mesh>
            <scale>0.001 0.001 0.001</scale>
            <uri>model://qb_hand_description/meshes/ph_knuckle.stl</uri>
          </mesh>
        </geometry>
      </collision>
      <collision name="r_palm_fixed_joint_lump__qbhand_right_little_proximal_link_collision_7">
        <pose frame="">-0.035509 0.00081 -0.21401 3.14159 1.57079 0.001593</pose>
        <geometry>
          <mesh>
            <scale>0.001 0.001 0.001</scale>
            <uri>model://qb_hand_description/meshes/ph_small.stl</uri>
          </mesh>
        </geometry>
      </collision>
      <collision name="r_palm_fixed_joint_lump__qbhand_right_little_middle_link_collision_8">
        <pose frame="">-0.035527 0.000862 -0.23601 3.14159 1.57079 0.001593</pose>
        <geometry>
          <mesh>
            <scale>0.001 0.001 0.001</scale>
            <uri>model://qb_hand_description/meshes/ph_small.stl</uri>
          </mesh>
        </geometry>
      </collision>
      <collision name="r_palm_fixed_joint_lump__qbhand_right_little_distal_link_collision_9">
        <pose frame="">-0.035544 0.000915 -0.25801 3.14159 1.57079 0.001593</pose>
        <geometry>
          <mesh>
            <scale>0.001 0.001 0.001</scale>
            <uri>model://qb_hand_description/meshes/ph_distal.stl</uri>
          </mesh>
        </geometry>
      </collision>
      <collision name="r_palm_fixed_joint_lump__qbhand_right_middle_knuckle_link_collision_10">
        <pose frame="">0.004501 0.000722 -0.20401 -1.57319 -0 3.14</pose>
        <geometry>
          <mesh>
            <scale>0.001 0.001 0.001</scale>
            <uri>model://qb_hand_description/meshes/ph_knuckle.stl</uri>
          </mesh>
        </geometry>
      </collision>
      <collision name="r_palm_fixed_joint_lump__qbhand_right_middle_proximal_link_collision_11">
        <pose frame="">0.004491 0.000775 -0.22601 3.14159 1.57079 0.001593</pose>
        <geometry>
          <mesh>
            <scale>0.001 0.001 0.001</scale>
            <uri>model://qb_hand_description/meshes/ph_medium.stl</uri>
          </mesh>
        </geometry>
      </collision>
      <collision name="r_palm_fixed_joint_lump__qbhand_right_middle_middle_link_collision_12">
        <pose frame="">0.004467 0.000846 -0.25601 3.14159 1.57079 0.001593</pose>
        <geometry>
          <mesh>
            <scale>0.001 0.001 0.001</scale>
            <uri>model://qb_hand_description/meshes/ph_small.stl</uri>
          </mesh>
        </geometry>
      </collision>
      <collision name="r_palm_fixed_joint_lump__qbhand_right_middle_distal_link_collision_13">
        <pose frame="">0.00445 0.000899 -0.27801 3.14159 1.57079 0.001593</pose>
        <geometry>
          <mesh>
            <scale>0.001 0.001 0.001</scale>
            <uri>model://qb_hand_description/meshes/ph_distal.stl</uri>
          </mesh>
        </geometry>
      </collision>
      <collision name="r_palm_fixed_joint_lump__qbhand_right_ring_knuckle_link_collision_14">
        <pose frame="">-0.015499 0.000737 -0.19701 -1.57319 -0 3.14</pose>
        <geometry>
          <mesh>
            <scale>0.001 0.001 0.001</scale>
            <uri>model://qb_hand_description/meshes/ph_knuckle.stl</uri>
          </mesh>
        </geometry>
      </collision>
      <collision name="r_palm_fixed_joint_lump__qbhand_right_ring_proximal_link_collision_15">
        <pose frame="">-0.015509 0.00079 -0.21901 3.14159 1.57079 0.001593</pose>
        <geometry>
          <mesh>
            <scale>0.001 0.001 0.001</scale>
            <uri>model://qb_hand_description/meshes/ph_medium.stl</uri>
          </mesh>
        </geometry>
      </collision>
      <collision name="r_palm_fixed_joint_lump__qbhand_right_ring_middle_link_collision_16">
        <pose frame="">-0.015533 0.000862 -0.24901 3.14159 1.57079 0.001593</pose>
        <geometry>
          <mesh>
            <scale>0.001 0.001 0.001</scale>
            <uri>model://qb_hand_description/meshes/ph_small.stl</uri>
          </mesh>
        </geometry>
      </collision>
      <collision name="r_palm_fixed_joint_lump__qbhand_right_ring_distal_link_collision_17">
        <pose frame="">-0.01555 0.000914 -0.27101 3.14159 1.57079 0.001593</pose>
        <geometry>
          <mesh>
            <scale>0.001 0.001 0.001</scale>
            <uri>model://qb_hand_description/meshes/ph_distal.stl</uri>
          </mesh>
        </geometry>
      </collision>
      <collision name="r_palm_fixed_joint_lump__qbhand_right_thumb_knuckle_link_collision_18">
        <pose frame="">0.048026 0.016549 -0.160472 -3.13841 -4e-06 -0</pose>
        <geometry>
          <mesh>
            <scale>0.001 0.001 0.001</scale>
            <uri>model://qb_hand_description/meshes/ph_thumb_r.stl</uri>
          </mesh>
        </geometry>
      </collision>
      <collision name="r_palm_fixed_joint_lump__qbhand_right_thumb_proximal_link_collision_19">
        <pose frame="">0.086526 0.020541 -0.157959 1.99478 -4e-06 -0</pose>
        <geometry>
          <mesh>
            <scale>0.001 0.001 0.001</scale>
            <uri>model://qb_hand_description/meshes/ph_small.stl</uri>
          </mesh>
        </geometry>
      </collision>
      <collision name="r_palm_fixed_joint_lump__qbhand_right_thumb_distal_link_collision_20">
        <pose frame="">0.108526 0.020541 -0.157959 1.99478 -4e-06 -0</pose>
        <geometry>
          <mesh>
            <scale>0.001 0.001 0.001</scale>
            <uri>model://qb_hand_description/meshes/ph_distal.stl</uri>
          </mesh>
        </geometry>
      </collision>
      <visual name="r_palm_visual">
        <pose frame="">0 0 0 -1.5708 0 0</pose>
        <geometry>
          <mesh>
            <scale>1 1 1</scale>
            <uri>model://eve_r3_description/meshes/palm.obj</uri>
          </mesh>
        </geometry>
      </visual>
      <visual name="r_palm_fixed_joint_lump__qbhand_right_base_link_visual_1">
        <pose frame="">0 0 -0.06 3.14 -0 3.14</pose>
        <geometry>
          <mesh>
            <scale>0.001 0.001 0.001</scale>
            <uri>model://qb_hand_description/meshes/flange_iso_04.stl</uri>
          </mesh>
        </geometry>
      </visual>
      <visual name="r_palm_fixed_joint_lump__qbhand_right_palm_link_visual_2">
        <pose frame="">0.004523 0.014722 -0.203977 -1.57319 -0 3.14</pose>
        <geometry>
          <mesh>
            <scale>0.001 0.001 0.001</scale>
            <uri>model://qb_hand_description/meshes/palm_pinch_r.stl</uri>
          </mesh>
        </geometry>
      </visual>
      <visual name="r_palm_fixed_joint_lump__qbhand_right_index_knuckle_link_visual_3">
        <pose frame="">0.024501 0.000674 -0.19701 -1.57319 -0 3.14</pose>
        <geometry>
          <mesh>
            <scale>0.001 0.001 0.001</scale>
            <uri>model://qb_hand_description/meshes/ph_knuckle.stl</uri>
          </mesh>
        </geometry>
      </visual>
      <visual name="r_palm_fixed_joint_lump__qbhand_right_index_proximal_link_visual_4">
        <pose frame="">0.024491 0.000726 -0.21901 3.14159 1.57079 0.001593</pose>
        <geometry>
          <mesh>
            <scale>0.001 0.001 0.001</scale>
            <uri>model://qb_hand_description/meshes/ph_medium.stl</uri>
          </mesh>
        </geometry>
      </visual>
      <visual name="r_palm_fixed_joint_lump__qbhand_right_index_middle_link_visual_5">
        <pose frame="">0.024467 0.000798 -0.24901 3.14159 1.57079 0.001593</pose>
        <geometry>
          <mesh>
            <scale>0.001 0.001 0.001</scale>
            <uri>model://qb_hand_description/meshes/ph_small.stl</uri>
          </mesh>
        </geometry>
      </visual>
      <visual name="r_palm_fixed_joint_lump__qbhand_right_index_distal_link_visual_6">
        <pose frame="">0.02445 0.00085 -0.27101 3.14159 1.57079 0.001593</pose>
        <geometry>
          <mesh>
            <scale>0.001 0.001 0.001</scale>
            <uri>model://qb_hand_description/meshes/ph_distal.stl</uri>
          </mesh>
        </geometry>
      </visual>
      <visual name="r_palm_fixed_joint_lump__qbhand_right_little_knuckle_link_visual_7">
        <pose frame="">-0.035499 0.000757 -0.19201 -1.57319 -0 3.14</pose>
        <geometry>
          <mesh>
            <scale>0.001 0.001 0.001</scale>
            <uri>model://qb_hand_description/meshes/ph_knuckle.stl</uri>
          </mesh>
        </geometry>
      </visual>
      <visual name="r_palm_fixed_joint_lump__qbhand_right_little_proximal_link_visual_8">
        <pose frame="">-0.035509 0.00081 -0.21401 3.14159 1.57079 0.001593</pose>
        <geometry>
          <mesh>
            <scale>0.001 0.001 0.001</scale>
            <uri>model://qb_hand_description/meshes/ph_small.stl</uri>
          </mesh>
        </geometry>
      </visual>
      <visual name="r_palm_fixed_joint_lump__qbhand_right_little_middle_link_visual_9">
        <pose frame="">-0.035527 0.000862 -0.23601 3.14159 1.57079 0.001593</pose>
        <geometry>
          <mesh>
            <scale>0.001 0.001 0.001</scale>
            <uri>model://qb_hand_description/meshes/ph_small.stl</uri>
          </mesh>
        </geometry>
      </visual>
      <visual name="r_palm_fixed_joint_lump__qbhand_right_little_distal_link_visual_10">
        <pose frame="">-0.035544 0.000915 -0.25801 3.14159 1.57079 0.001593</pose>
        <geometry>
          <mesh>
            <scale>0.001 0.001 0.001</scale>
            <uri>model://qb_hand_description/meshes/ph_distal.stl</uri>
          </mesh>
        </geometry>
      </visual>
      <visual name="r_palm_fixed_joint_lump__qbhand_right_middle_knuckle_link_visual_11">
        <pose frame="">0.004501 0.000722 -0.20401 -1.57319 -0 3.14</pose>
        <geometry>
          <mesh>
            <scale>0.001 0.001 0.001</scale>
            <uri>model://qb_hand_description/meshes/ph_knuckle.stl</uri>
          </mesh>
        </geometry>
      </visual>
      <visual name="r_palm_fixed_joint_lump__qbhand_right_middle_proximal_link_visual_12">
        <pose frame="">0.004491 0.000775 -0.22601 3.14159 1.57079 0.001593</pose>
        <geometry>
          <mesh>
            <scale>0.001 0.001 0.001</scale>
            <uri>model://qb_hand_description/meshes/ph_medium.stl</uri>
          </mesh>
        </geometry>
      </visual>
      <visual name="r_palm_fixed_joint_lump__qbhand_right_middle_middle_link_visual_13">
        <pose frame="">0.004467 0.000846 -0.25601 3.14159 1.57079 0.001593</pose>
        <geometry>
          <mesh>
            <scale>0.001 0.001 0.001</scale>
            <uri>model://qb_hand_description/meshes/ph_small.stl</uri>
          </mesh>
        </geometry>
      </visual>
      <visual name="r_palm_fixed_joint_lump__qbhand_right_middle_distal_link_visual_14">
        <pose frame="">0.00445 0.000899 -0.27801 3.14159 1.57079 0.001593</pose>
        <geometry>
          <mesh>
            <scale>0.001 0.001 0.001</scale>
            <uri>model://qb_hand_description/meshes/ph_distal.stl</uri>
          </mesh>
        </geometry>
      </visual>
      <visual name="r_palm_fixed_joint_lump__qbhand_right_ring_knuckle_link_visual_15">
        <pose frame="">-0.015499 0.000737 -0.19701 -1.57319 -0 3.14</pose>
        <geometry>
          <mesh>
            <scale>0.001 0.001 0.001</scale>
            <uri>model://qb_hand_description/meshes/ph_knuckle.stl</uri>
          </mesh>
        </geometry>
      </visual>
      <visual name="r_palm_fixed_joint_lump__qbhand_right_ring_proximal_link_visual_16">
        <pose frame="">-0.015509 0.00079 -0.21901 3.14159 1.57079 0.001593</pose>
        <geometry>
          <mesh>
            <scale>0.001 0.001 0.001</scale>
            <uri>model://qb_hand_description/meshes/ph_medium.stl</uri>
          </mesh>
        </geometry>
      </visual>
      <visual name="r_palm_fixed_joint_lump__qbhand_right_ring_middle_link_visual_17">
        <pose frame="">-0.015533 0.000862 -0.24901 3.14159 1.57079 0.001593</pose>
        <geometry>
          <mesh>
            <scale>0.001 0.001 0.001</scale>
            <uri>model://qb_hand_description/meshes/ph_small.stl</uri>
          </mesh>
        </geometry>
      </visual>
      <visual name="r_palm_fixed_joint_lump__qbhand_right_ring_distal_link_visual_18">
        <pose frame="">-0.01555 0.000914 -0.27101 3.14159 1.57079 0.001593</pose>
        <geometry>
          <mesh>
            <scale>0.001 0.001 0.001</scale>
            <uri>model://qb_hand_description/meshes/ph_distal.stl</uri>
          </mesh>
        </geometry>
      </visual>
      <visual name="r_palm_fixed_joint_lump__qbhand_right_thumb_knuckle_link_visual_19">
        <pose frame="">0.048026 0.016549 -0.160472 -3.13841 -4e-06 -0</pose>
        <geometry>
          <mesh>
            <scale>0.001 0.001 0.001</scale>
            <uri>model://qb_hand_description/meshes/ph_thumb_r.stl</uri>
          </mesh>
        </geometry>
      </visual>
      <visual name="r_palm_fixed_joint_lump__qbhand_right_thumb_proximal_link_visual_20">
        <pose frame="">0.086526 0.020541 -0.157959 1.99478 -4e-06 -0</pose>
        <geometry>
          <mesh>
            <scale>0.001 0.001 0.001</scale>
            <uri>model://qb_hand_description/meshes/ph_small.stl</uri>
          </mesh>
        </geometry>
      </visual>
      <visual name="r_palm_fixed_joint_lump__qbhand_right_thumb_distal_link_visual_21">
        <pose frame="">0.108526 0.020541 -0.157959 1.99478 -4e-06 -0</pose>
        <geometry>
          <mesh>
            <scale>0.001 0.001 0.001</scale>
            <uri>model://qb_hand_description/meshes/ph_distal.stl</uri>
          </mesh>
        </geometry>
      </visual>
    </link>
    <joint name="j_r_wrist_x" type="revolute">
      <child>r_palm</child>
      <parent>r_wrist</parent>
      <axis>
        <xyz>1 0 -0</xyz>
        <limit>
          <lower>-0.523599</lower>
          <upper>1.5708</upper>
          <effort>-1</effort>
          <velocity>-1</velocity>
        </limit>
        <dynamics>
          <spring_reference>0</spring_reference>
          <spring_stiffness>0</spring_stiffness>
        </dynamics>
        <use_parent_model_frame>1</use_parent_model_frame>
      </axis>
    </joint>
  </model>
</sdf>
