<?xml version="1.0"?>
<sdf version="1.5">
  <model name="eve_r3_upper_body_no_hands">
    <link name="abdomen">
      <pose frame="">0 0 0 0 -0 0</pose>
      <inertial>
        <pose frame="">-0.055587 0.00157 0.131108 0 -0 0</pose>
        <mass>3.43818</mass>
        <inertia>
          <ixx>0.0560722</ixx>
          <ixy>0.00070118</ixy>
          <ixz>-0.014681</ixz>
          <iyy>0.0543572</iyy>
          <iyz>-0.00188443</iyz>
          <izz>0.0201674</izz>
        </inertia>
      </inertial>
      <visual name="abdomen_visual">
        <pose frame="">0 0 0 1.5708 -0 1.5708</pose>
        <geometry>
          <mesh>
            <scale>1 1 1</scale>
            <uri>model://eve_r3_description/meshes/abdomen.obj</uri>
          </mesh>
        </geometry>
      </visual>
    </link>
    <link name="pelvis">
      <pose frame="">0 0 0 0 -0 0</pose>
      <inertial>
        <pose frame="">-0.02336 -0.007712 0.420206 0 -0 0</pose>
        <mass>10.0418</mass>
        <inertia>
          <ixx>0.172034</ixx>
          <ixy>0.00142736</ixy>
          <ixz>0.0133394</ixz>
          <iyy>0.164389</iyy>
          <iyz>-0.00928197</iyz>
          <izz>0.0650147</izz>
        </inertia>
      </inertial>
      <visual name="pelvis_visual">
        <pose frame="">0 0 0 1.5708 -0 1.5708</pose>
        <geometry>
          <mesh>
            <scale>1 1 1</scale>
            <uri>model://eve_r3_description/meshes/torso.obj</uri>
          </mesh>
        </geometry>
      </visual>
    </link>
    <joint name="j_hip_z" type="revolute">
      <child>pelvis</child>
      <parent>abdomen</parent>
      <axis>
        <xyz>0 0 1</xyz>
        <limit>
          <lower>-1.0472</lower>
          <upper>1.0472</upper>
          <effort>-1</effort>
          <velocity>-1</velocity>
        </limit>
        <dynamics>
          <spring_reference>0</spring_reference>
          <spring_stiffness>0</spring_stiffness>
        </dynamics>
        <use_parent_model_frame>1</use_parent_model_frame>
      </axis>
    </joint>
    <link name="l_scapula">
      <pose frame="">0.010525 0.207221 0.545525 0.253262 -0 -0.261799</pose>
      <inertial>
        <pose frame="">-0.000611 -0.063067 0.030325 0 -0 0</pose>
        <mass>2.75567</mass>
        <inertia>
          <ixx>0.00936557</ixx>
          <ixy>2.264e-05</ixy>
          <ixz>7.112e-05</ixz>
          <iyy>0.0107902</iyy>
          <iyz>-0.0008423</iyz>
          <izz>0.0126776</izz>
        </inertia>
      </inertial>
      <visual name="l_scapula_visual">
        <pose frame="">0 0 0 1.5708 -0 3.14159</pose>
        <geometry>
          <mesh>
            <scale>1 1 1</scale>
            <uri>model://eve_r3_description/meshes/scapula.obj</uri>
          </mesh>
        </geometry>
      </visual>
    </link>
    <joint name="j_l_shoulder_y" type="revolute">
      <child>l_scapula</child>
      <parent>pelvis</parent>
      <axis>
        <xyz>0.250562 0.935113 0.250563</xyz>
        <limit>
          <lower>-2.42409</lower>
          <upper>0.98105</upper>
          <effort>-1</effort>
          <velocity>-1</velocity>
        </limit>
        <dynamics>
          <spring_reference>0</spring_reference>
          <spring_stiffness>0</spring_stiffness>
        </dynamics>
        <use_parent_model_frame>1</use_parent_model_frame>
      </axis>
    </joint>
    <link name="l_shoulder">
      <pose frame="">0.010525 0.207221 0.545525 -0 -0 -0.261799</pose>
      <inertial>
        <pose frame="">0 0.000706 -0.019754 0 -0 0</pose>
        <mass>0.702657</mass>
        <inertia>
          <ixx>0.00115475</ixx>
          <ixy>-3.2e-07</ixy>
          <ixz>1.3e-07</ixz>
          <iyy>0.00143715</iyy>
          <iyz>-2.63e-06</iyz>
          <izz>0.00094634</izz>
        </inertia>
      </inertial>
      <visual name="l_shoulder_visual">
        <pose frame="">0 0 0 3.14159 -0 0</pose>
        <geometry>
          <mesh>
            <scale>1 1 1</scale>
            <uri>model://eve_r3_description/meshes/shoulder.obj</uri>
          </mesh>
        </geometry>
      </visual>
    </link>
    <joint name="j_l_shoulder_x" type="revolute">
      <child>l_shoulder</child>
      <parent>l_scapula</parent>
      <axis>
        <xyz>0.965926 -0.258819 0</xyz>
        <limit>
          <lower>-0.0872665</lower>
          <upper>2.0944</upper>
          <effort>-1</effort>
          <velocity>-1</velocity>
        </limit>
        <dynamics>
          <spring_reference>0</spring_reference>
          <spring_stiffness>0</spring_stiffness>
        </dynamics>
        <use_parent_model_frame>1</use_parent_model_frame>
      </axis>
    </joint>
    <link name="l_upper_arm">
      <pose frame="">0.010525 0.207221 0.545525 -0 0 -0</pose>
      <inertial>
        <pose frame="">-0.006258 3.5e-05 -0.171877 0 -0 0</pose>
        <mass>2.92532</mass>
        <inertia>
          <ixx>0.0134165</ixx>
          <ixy>-6.4e-07</ixy>
          <ixz>-0.00029063</ixz>
          <iyy>0.0128785</iyy>
          <iyz>-3.08e-06</iyz>
          <izz>0.00487381</izz>
        </inertia>
      </inertial>
      <visual name="l_upper_arm_visual">
        <pose frame="">0 0 0 1.5708 -0 3.14159</pose>
        <geometry>
          <mesh>
            <scale>1 1 1</scale>
            <uri>model://eve_r3_description/meshes/upper_arm.obj</uri>
          </mesh>
        </geometry>
      </visual>
    </link>
    <joint name="j_l_shoulder_z" type="revolute">
      <child>l_upper_arm</child>
      <parent>l_shoulder</parent>
      <axis>
        <xyz>0 0 1</xyz>
        <limit>
          <lower>-1.46608</lower>
          <upper>0.541053</upper>
          <effort>-1</effort>
          <velocity>-1</velocity>
        </limit>
        <dynamics>
          <spring_reference>0</spring_reference>
          <spring_stiffness>0</spring_stiffness>
        </dynamics>
        <use_parent_model_frame>1</use_parent_model_frame>
      </axis>
    </joint>
    <link name="l_elbow">
      <pose frame="">0.010525 0.207221 0.231536 -0 0 -0</pose>
      <inertial>
        <pose frame="">5.5e-05 0 -0.008885 0 -0 0</pose>
        <mass>0.462616</mass>
        <inertia>
          <ixx>0.0008227</ixx>
          <ixy>-0</ixy>
          <ixz>9.6e-07</ixz>
          <iyy>0.00036441</iyy>
          <iyz>-0</iyz>
          <izz>0.00061472</izz>
        </inertia>
      </inertial>
      <visual name="l_elbow_visual">
        <pose frame="">0 0 0 3.14159 3e-06 -1.5708</pose>
        <geometry>
          <mesh>
            <scale>1 1 1</scale>
            <uri>model://eve_r3_description/meshes/elbow.obj</uri>
          </mesh>
        </geometry>
      </visual>
    </link>
    <joint name="j_l_elbow_y" type="revolute">
      <child>l_elbow</child>
      <parent>l_upper_arm</parent>
      <axis>
        <xyz>-0 1 -0</xyz>
        <limit>
          <lower>-2.18166</lower>
          <upper>0</upper>
          <effort>-1</effort>
          <velocity>-1</velocity>
        </limit>
        <dynamics>
          <spring_reference>0</spring_reference>
          <spring_stiffness>0</spring_stiffness>
        </dynamics>
        <use_parent_model_frame>1</use_parent_model_frame>
      </axis>
    </joint>
    <link name="l_lower_arm">
      <pose frame="">0.010525 0.207221 0.231536 -0 0 -0</pose>
      <inertial>
        <pose frame="">-4.3e-05 3.1e-05 -0.13751 0 -0 0</pose>
        <mass>1.63933</mass>
        <inertia>
          <ixx>0.00678741</ixx>
          <ixy>1.11e-06</ixy>
          <ixz>-1.253e-05</ixz>
          <iyy>0.00706746</iyy>
          <iyz>1.485e-05</iyz>
          <izz>0.00183806</izz>
        </inertia>
      </inertial>
      <visual name="l_lower_arm_visual">
        <pose frame="">0 0 -0.29285 3.14159 3e-06 3.14159</pose>
        <geometry>
          <mesh>
            <scale>1 1 1</scale>
            <uri>model://eve_r3_description/meshes/forearm.obj</uri>
          </mesh>
        </geometry>
      </visual>
    </link>
    <joint name="j_l_elbow_z" type="revolute">
      <child>l_lower_arm</child>
      <parent>l_elbow</parent>
      <axis>
        <xyz>0 0 1</xyz>
        <limit>
          <lower>-1.5708</lower>
          <upper>0.7854</upper>
          <effort>-1</effort>
          <velocity>-1</velocity>
        </limit>
        <dynamics>
          <spring_reference>0</spring_reference>
          <spring_stiffness>0</spring_stiffness>
        </dynamics>
        <use_parent_model_frame>1</use_parent_model_frame>
      </axis>
    </joint>
    <link name="l_wrist">
      <pose frame="">0.010525 0.207221 -0.061314 -0 0 -0</pose>
      <inertial>
        <pose frame="">0.002401 0.000797 -0.001254 0 -0 0</pose>
        <mass>0.303634</mass>
        <inertia>
          <ixx>0.00018188</ixx>
          <ixy>2.27e-06</ixy>
          <ixz>-2.16e-06</ixz>
          <iyy>0.00016139</iyy>
          <iyz>-9.5e-07</iyz>
          <izz>0.00027335</izz>
        </inertia>
      </inertial>
      <visual name="l_wrist_visual">
        <pose frame="">0 0 0 0 -0 1.5708</pose>
        <geometry>
          <mesh>
            <scale>1 1 1</scale>
            <uri>model://eve_r3_description/meshes/wrist.obj</uri>
          </mesh>
        </geometry>
      </visual>
    </link>
    <joint name="j_l_wrist_y" type="revolute">
      <child>l_wrist</child>
      <parent>l_lower_arm</parent>
      <axis>
        <xyz>-0 1 -0</xyz>
        <limit>
          <lower>-0.785398</lower>
          <upper>0.785398</upper>
          <effort>-1</effort>
          <velocity>-1</velocity>
        </limit>
        <dynamics>
          <spring_reference>0</spring_reference>
          <spring_stiffness>0</spring_stiffness>
        </dynamics>
        <use_parent_model_frame>1</use_parent_model_frame>
      </axis>
    </joint>
    <link name="l_palm">
      <pose frame="">0.010525 0.207221 -0.061314 -0 0 -0</pose>
      <inertial>
        <pose frame="">0.006185 -0.003467 -0.018888 0 -0 0</pose>
        <mass>0.148638</mass>
        <inertia>
          <ixx>0.0001177</ixx>
          <ixy>-2.72e-06</ixy>
          <ixz>-1.656e-05</ixz>
          <iyy>0.00028407</iyy>
          <iyz>-5.49e-06</iyz>
          <izz>0.00021805</izz>
        </inertia>
      </inertial>
      <visual name="l_palm_visual">
        <pose frame="">0 0 0 -1.5708 -0 3.14159</pose>
        <geometry>
          <mesh>
            <scale>1 1 1</scale>
            <uri>model://eve_r3_description/meshes/palm.obj</uri>
          </mesh>
        </geometry>
      </visual>
    </link>
    <joint name="j_l_wrist_x" type="revolute">
      <child>l_palm</child>
      <parent>l_wrist</parent>
      <axis>
        <xyz>1 -0 -0</xyz>
        <limit>
          <lower>-1.5708</lower>
          <upper>0.523599</upper>
          <effort>-1</effort>
          <velocity>-1</velocity>
        </limit>
        <dynamics>
          <spring_reference>0</spring_reference>
          <spring_stiffness>0</spring_stiffness>
        </dynamics>
        <use_parent_model_frame>1</use_parent_model_frame>
      </axis>
    </joint>
    <link name="head">
      <pose frame="">-0.004458 0 0.680766 0 -0 0</pose>
      <inertial>
        <pose frame="">0.012724 -0.003269 0.070532 0 -0 0</pose>
        <mass>2.355</mass>
        <inertia>
          <ixx>0.0171994</ixx>
          <ixy>-8.079e-05</ixy>
          <ixz>-0.0013284</ixz>
          <iyy>0.0196904</iyy>
          <iyz>0.00023833</iyz>
          <izz>0.0077437</izz>
        </inertia>
      </inertial>
      <visual name="head_visual">
        <pose frame="">0 0 0 1.5708 -0 1.5708</pose>
        <geometry>
          <mesh>
            <scale>1 1 1</scale>
            <uri>model://eve_r3_description/meshes/head.obj</uri>
          </mesh>
        </geometry>
        
      </visual>
      <gravity>1</gravity>
      <velocity_decay/>
      <sensor name="realsense" type="camera">
        <camera name="__default__">
          <image>
            <width>640</width>
            <height>480</height>
            <format>R8G8B8</format>
          </image>
          <horizontal_fov>1.48702</horizontal_fov>
          <clip>
            <near>0.2</near>
            <far>10</far>
          </clip>
        </camera>
        <update_rate>6</update_rate>
        <pose frame="">0.116669 0 0.17015 0 0.174533 0</pose>
      </sensor>
    </link>
    <joint name="j_neck_y" type="revolute">
      <child>head</child>
      <parent>pelvis</parent>
      <axis>
        <xyz>0 1 0</xyz>
        <limit>
          <lower>-0.0872665</lower>
          <upper>0.698132</upper>
          <effort>-1</effort>
          <velocity>-1</velocity>
        </limit>
        <dynamics>
          <spring_reference>0</spring_reference>
          <spring_stiffness>0</spring_stiffness>
        </dynamics>
        <use_parent_model_frame>1</use_parent_model_frame>
      </axis>
    </joint>
    <link name="r_scapula">
      <pose frame="">0.010525 -0.207221 0.545525 -0.253262 -0 0.261799</pose>
      <inertial>
        <pose frame="">0.000611 0.063067 0.030325 0 -0 0</pose>
        <mass>2.75567</mass>
        <inertia>
          <ixx>0.00936557</ixx>
          <ixy>2.264e-05</ixy>
          <ixz>-7.112e-05</ixz>
          <iyy>0.0107902</iyy>
          <iyz>0.0008423</iyz>
          <izz>0.0126776</izz>
        </inertia>
      </inertial>
      <visual name="r_scapula_visual">
        <pose frame="">0 0 0 1.5708 -0 0</pose>
        <geometry>
          <mesh>
            <scale>1 1 1</scale>
            <uri>model://eve_r3_description/meshes/scapula.obj</uri>
          </mesh>
        </geometry>
      </visual>
    </link>
    <joint name="j_r_shoulder_y" type="revolute">
      <child>r_scapula</child>
      <parent>pelvis</parent>
      <axis>
        <xyz>-0.250562 0.935113 -0.250563</xyz>
        <limit>
          <lower>-2.42409</lower>
          <upper>0.98105</upper>
          <effort>-1</effort>
          <velocity>-1</velocity>
        </limit>
        <dynamics>
          <spring_reference>0</spring_reference>
          <spring_stiffness>0</spring_stiffness>
        </dynamics>
        <use_parent_model_frame>1</use_parent_model_frame>
      </axis>
    </joint>
    <link name="r_shoulder">
      <pose frame="">0.010525 -0.207221 0.545525 0 -0 0.261799</pose>
      <inertial>
        <pose frame="">0 -0.000706 -0.019755 0 -0 0</pose>
        <mass>0.702643</mass>
        <inertia>
          <ixx>0.00115475</ixx>
          <ixy>-3.2e-07</ixy>
          <ixz>-1.4e-07</ixz>
          <iyy>0.00143713</iyy>
          <iyz>2.63e-06</iyz>
          <izz>0.00094633</izz>
        </inertia>
      </inertial>
      <visual name="r_shoulder_visual">
        <pose frame="">0 0 0 3.14159 -0 0</pose>
        <geometry>
          <mesh>
            <scale>1 1 1</scale>
            <uri>model://eve_r3_description/meshes/shoulder.obj</uri>
          </mesh>
        </geometry>
      </visual>
    </link>
    <joint name="j_r_shoulder_x" type="revolute">
      <child>r_shoulder</child>
      <parent>r_scapula</parent>
      <axis>
        <xyz>0.965926 0.258819 0</xyz>
        <limit>
          <lower>-2.0944</lower>
          <upper>0.0872665</upper>
          <effort>-1</effort>
          <velocity>-1</velocity>
        </limit>
        <dynamics>
          <spring_reference>0</spring_reference>
          <spring_stiffness>0</spring_stiffness>
        </dynamics>
        <use_parent_model_frame>1</use_parent_model_frame>
      </axis>
    </joint>
    <link name="r_upper_arm">
      <pose frame="">0.010525 -0.207221 0.545525 0 0 0</pose>
      <inertial>
        <pose frame="">-0.006258 3.5e-05 -0.171877 0 -0 0</pose>
        <mass>2.92532</mass>
        <inertia>
          <ixx>0.0134165</ixx>
          <ixy>-6.4e-07</ixy>
          <ixz>-0.00029063</ixz>
          <iyy>0.0128785</iyy>
          <iyz>-3.08e-06</iyz>
          <izz>0.00487381</izz>
        </inertia>
      </inertial>
      <visual name="r_upper_arm_visual">
        <pose frame="">0 0 0 1.5708 -0 3.14159</pose>
        <geometry>
          <mesh>
            <scale>1 1 1</scale>
            <uri>model://eve_r3_description/meshes/upper_arm.obj</uri>
          </mesh>
        </geometry>
      </visual>
    </link>
    <joint name="j_r_shoulder_z" type="revolute">
      <child>r_upper_arm</child>
      <parent>r_shoulder</parent>
      <axis>
        <xyz>0 -0 1</xyz>
        <limit>
          <lower>-0.541053</lower>
          <upper>1.46608</upper>
          <effort>-1</effort>
          <velocity>-1</velocity>
        </limit>
        <dynamics>
          <spring_reference>0</spring_reference>
          <spring_stiffness>0</spring_stiffness>
        </dynamics>
        <use_parent_model_frame>1</use_parent_model_frame>
      </axis>
    </joint>
    <link name="r_elbow">
      <pose frame="">0.010525 -0.207221 0.231536 0 0 0</pose>
      <inertial>
        <pose frame="">5.5e-05 0 -0.008885 0 -0 0</pose>
        <mass>0.462616</mass>
        <inertia>
          <ixx>0.0008227</ixx>
          <ixy>-0</ixy>
          <ixz>9.6e-07</ixz>
          <iyy>0.00036441</iyy>
          <iyz>-0</iyz>
          <izz>0.00061472</izz>
        </inertia>
      </inertial>
      <visual name="r_elbow_visual">
        <pose frame="">0 0 0 3.14159 3e-06 -1.5708</pose>
        <geometry>
          <mesh>
            <scale>1 1 1</scale>
            <uri>model://eve_r3_description/meshes/elbow.obj</uri>
          </mesh>
        </geometry>
      </visual>
    </link>
    <joint name="j_r_elbow_y" type="revolute">
      <child>r_elbow</child>
      <parent>r_upper_arm</parent>
      <axis>
        <xyz>0 1 0</xyz>
        <limit>
          <lower>-2.18166</lower>
          <upper>0</upper>
          <effort>-1</effort>
          <velocity>-1</velocity>
        </limit>
        <dynamics>
          <spring_reference>0</spring_reference>
          <spring_stiffness>0</spring_stiffness>
        </dynamics>
        <use_parent_model_frame>1</use_parent_model_frame>
      </axis>
    </joint>
    <link name="r_lower_arm">
      <pose frame="">0.010525 -0.207221 0.231536 0 0 0</pose>
      <inertial>
        <pose frame="">-4.3e-05 3.1e-05 -0.13751 0 -0 0</pose>
        <mass>1.63933</mass>
        <inertia>
          <ixx>0.00678741</ixx>
          <ixy>1.11e-06</ixy>
          <ixz>-1.253e-05</ixz>
          <iyy>0.00706746</iyy>
          <iyz>1.485e-05</iyz>
          <izz>0.00183806</izz>
        </inertia>
      </inertial>
      <visual name="r_lower_arm_visual">
        <pose frame="">0 0 -0.29285 3.14159 3e-06 3.14159</pose>
        <geometry>
          <mesh>
            <scale>1 1 1</scale>
            <uri>model://eve_r3_description/meshes/forearm.obj</uri>
          </mesh>
        </geometry>
      </visual>
    </link>
    <joint name="j_r_elbow_z" type="revolute">
      <child>r_lower_arm</child>
      <parent>r_elbow</parent>
      <axis>
        <xyz>0 -0 1</xyz>
        <limit>
          <lower>-0.7854</lower>
          <upper>1.5708</upper>
          <effort>-1</effort>
          <velocity>-1</velocity>
        </limit>
        <dynamics>
          <spring_reference>0</spring_reference>
          <spring_stiffness>0</spring_stiffness>
        </dynamics>
        <use_parent_model_frame>1</use_parent_model_frame>
      </axis>
    </joint>
    <link name="r_wrist">
      <pose frame="">0.010525 -0.207221 -0.061314 0 0 0</pose>
      <inertial>
        <pose frame="">0.002401 0.000797 -0.001254 0 -0 0</pose>
        <mass>0.303634</mass>
        <inertia>
          <ixx>0.00018188</ixx>
          <ixy>2.27e-06</ixy>
          <ixz>-2.16e-06</ixz>
          <iyy>0.00016139</iyy>
          <iyz>-9.5e-07</iyz>
          <izz>0.00027335</izz>
        </inertia>
      </inertial>
      <visual name="r_wrist_visual">
        <pose frame="">0 0 0 0 -0 1.5708</pose>
        <geometry>
          <mesh>
            <scale>1 1 1</scale>
            <uri>model://eve_r3_description/meshes/wrist.obj</uri>
          </mesh>
        </geometry>
      </visual>
    </link>
    <joint name="j_r_wrist_y" type="revolute">
      <child>r_wrist</child>
      <parent>r_lower_arm</parent>
      <axis>
        <xyz>0 1 0</xyz>
        <limit>
          <lower>-0.785398</lower>
          <upper>0.785398</upper>
          <effort>-1</effort>
          <velocity>-1</velocity>
        </limit>
        <dynamics>
          <spring_reference>0</spring_reference>
          <spring_stiffness>0</spring_stiffness>
        </dynamics>
        <use_parent_model_frame>1</use_parent_model_frame>
      </axis>
    </joint>
    <link name="r_palm">
      <pose frame="">0.010525 -0.207221 -0.061314 0 0 0</pose>
      <inertial>
        <pose frame="">0.006185 -0.003467 -0.018888 0 -0 0</pose>
        <mass>0.148638</mass>
        <inertia>
          <ixx>0.0001177</ixx>
          <ixy>-2.72e-06</ixy>
          <ixz>-1.656e-05</ixz>
          <iyy>0.00028407</iyy>
          <iyz>-5.49e-06</iyz>
          <izz>0.00021805</izz>
        </inertia>
      </inertial>
      <visual name="r_palm_visual">
        <pose frame="">0 0 0 -1.5708 0 0</pose>
        <geometry>
          <mesh>
            <scale>1 1 1</scale>
            <uri>model://eve_r3_description/meshes/palm.obj</uri>
          </mesh>
        </geometry>
      </visual>
    </link>
    <joint name="j_r_wrist_x" type="revolute">
      <child>r_palm</child>
      <parent>r_wrist</parent>
      <axis>
        <xyz>1 0 -0</xyz>
        <limit>
          <lower>-0.523599</lower>
          <upper>1.5708</upper>
          <effort>-1</effort>
          <velocity>-1</velocity>
        </limit>
        <dynamics>
          <spring_reference>0</spring_reference>
          <spring_stiffness>0</spring_stiffness>
        </dynamics>
        <use_parent_model_frame>1</use_parent_model_frame>
      </axis>
    </joint>
  </model>
</sdf>
